Workbook

Sheet Januari
A1: CABANG | B1: JUMLAH PELANGGAN DESEMBER 2024 | C1: JUMLAH PELANGGAN BULAN JANUARI | D1: PENDAPATAN AIR BULAN DESEMBER 2024 | E1: PENDAPATAN AIR BULAN JANUARI | F1: SELISIH PENDAPATAN | G1: PRESENTASE PENDAPATAN | H1: KONSUMSI GOL 2 BULAN DESEMBER 2024 | I1: KONSUMSI GOL 2 BULAN JANUARI | J1: KONSUMSI TOTAL BULAN DESEMBER 2024 | K1: KONSUMSI TOTAL BULAN JANUARI | L1: PRESENTASE KONSUMSI | M1: AIR DISTRIBUSI BULAN DESEMBER 2024 | N1: AIR DISTRIBUSI BULAN JANUARI | O1: SELISIH AIR DISTRIBUSI | P1: PRESENTASE SELISIH AIR DISTRIBUSI | Q1: AIR TERJUAL BULAN DESEMBER 2024 | R1: AIR TERJUAL BULAN JANUARI | S1: SELISIH AIR TERJUAL | T1: TKA BULAN DESEMBER 2024 | U1: TKA BULAN JANUARI | V1: PRESETASE TKA BULAN JANUARI | W1: PRESENTASE TKA BULAN FEBRUARI
A2: SIDOARJO | B2: 46406 | C2: 46450 | D2: 7668872800 | E2: 7744073901 | F2: =E2-D2 -> 75201101 | G2: =F2/D2 -> 0.0098060175 | H2: 672138 | I2: 691283 | J2: 884838 | K2: 891195 | L2: =K2/J2 -> 1.0071844 | M2: 1460240.4 | N2: 1461926.9 | O2: =N2-M2 -> 1686.4667 | P2: =O2/M2 -> 0.001154924 | Q2: 884838 | R2: 891195 | S2: =R2-Q2 -> 6357 | T2: =M2-Q2 -> 575402.41 | U2: =N2-R2 -> 570731.88 | V2: =T2/M2 -> 0.39404635 | W2: =U2/N2 -> 0.39039701
A3: GEDANGAN | B3: 34520 | C3: 34769 | D3: 5088762800 | E3: 5440680942 | F3: =E3-D3 -> 351918142 | G3: =F3/D3 -> 0.069155934 | H3: 447284 | I3: 486915 | J3: 579638 | K3: 616080 | L3: =K3/J3 -> 1.0628703 | M3: 995788.89 | N3: 967330.04 | O3: =N3-M3 -> -28458.85 | P3: =O3/M3 -> -0.0285792 | Q3: 579638 | R3: 616080 | S3: =R3-Q3 -> 36442 | T3: =M3-Q3 -> 416150.89 | U3: =N3-R3 -> 351250.04 | V3: =T3/M3 -> 0.41791076 | W3: =U3/N3 -> 0.36311292
A4: TAMAN | B4: 33828 | C4: 33811 | D4: 4477972850 | E4: 4766698773 | F4: =E4-D4 -> 288725923 | G4: =F4/D4 -> 0.064476926 | H4: 562800 | I4: 589039 | J4: 622583 | K4: 653602 | L4: =K4/J4 -> 1.0498231 | M4: 1135411.6 | N4: 1161556 | O4: =N4-M4 -> 26144.41 | P4: =O4/M4 -> 0.023026373 | Q4: 622583 | R4: 653602 | S4: =R4-Q4 -> 31019 | T4: =M4-Q4 -> 512828.55 | U4: =N4-R4 -> 507953.96 | V4: =T4/M4 -> 0.45166755 | W4: =U4/N4 -> 0.43730477
A5: WARU 1 | B5: 28075 | C5: 28116 | D5: 3825993000 | E5: 4029436166 | F5: =E5-D5 -> 203443166 | G5: =F5/D5 -> 0.053173951 | H5: 394033 | I5: 399443 | J5: 465551 | K5: 478438 | L5: =K5/J5 -> 1.0276812 | M5: 842911 | N5: 758750.78 | O5: =N5-M5 -> -84160.222 | P5: =O5/M5 -> -0.099844731 | Q5: 465551 | R5: 478438 | S5: =R5-Q5 -> 12887 | T5: =M5-Q5 -> 377360 | U5: =N5-R5 -> 280312.78 | V5: =T5/M5 -> 0.44768665 | W5: =U5/N5 -> 0.36943986
A6: WARU 2 | B6: 21208 | C6: 21216 | D6: 3054563900 | E6: 3237865121 | F6: =E6-D6 -> 183301221 | G6: =F6/D6 -> 0.060008966 | H6: 338382 | I6: 353354 | J6: 389282 | K6: 405708 | L6: =K6/J6 -> 1.0421956 | M6: 490952.2 | N6: 573968.82 | O6: =N6-M6 -> 83016.622 | P6: =O6/M6 -> 0.16909309 | Q6: 389282 | R6: 405708 | S6: =R6-Q6 -> 16426 | T6: =M6-Q6 -> 101670.2 | U6: =N6-R6 -> 168260.82 | V6: =T6/M6 -> 0.20708778 | W6: =U6/N6 -> 0.29315324
A7: PORONG | B7: 15809 | C7: 15780 | D7: 1817115100 | E7: 2243411191 | F7: =E7-D7 -> 426296091 | G7: =F7/D7 -> 0.23460049 | H7: 176421 | I7: 198846 | J7: 219766 | K7: 258896 | L7: =K7/J7 -> 1.178053 | M7: 384051.68 | N7: 362813.01 | O7: =N7-M7 -> -21238.667 | P7: =O7/M7 -> -0.055301585 | Q7: 219766 | R7: 258896 | S7: =R7-Q7 -> 39130 | T7: =M7-Q7 -> 164285.68 | U7: =N7-R7 -> 103917.01 | V7: =T7/M7 -> 0.42776972 | W7: =U7/N7 -> 0.2864203
A8: KRIAN | B8: 6502 | C8: 6486 | D8: 608544200 | E8: 755099850 | F8: =E8-D8 -> 146555650 | G8: =F8/D8 -> 0.24082992 | H8: 76832 | I8: 93004 | J8: 83487 | K8: 101684 | L8: =K8/J8 -> 1.2179621 | M8: 138644.95 | N8: 136229.65 | O8: =N8-M8 -> -2415.3 | P8: =O8/M8 -> -0.017420757 | Q8: 83487 | R8: 101684 | S8: =R8-Q8 -> 18197 | T8: =M8-Q8 -> 55157.95 | U8: =N8-R8 -> 34545.65 | V8: =T8/M8 -> 0.39783598 | W8: =U8/N8 -> 0.25358393
A9: TOTAL | B9: =SUM(B2:B8) -> 186348 | C9: =SUM(C2:C8) -> 186628 | D9: =SUM(D2:D8) -> 26541824650 | E9: =SUM(E2:E8) -> 28217265944 | H9: =SUM(H2:H8) -> 2667890 | I9: =SUM(I2:I8) -> 2811884 | J9: =SUM(J2:J8) -> 3245145 | K9: =SUM(K2:K8) -> 3405603 | M9: =SUM(M2:M8) -> 5448000.7 | N9: =SUM(N2:N8) -> 5422575.1 | Q9: =SUM(Q2:Q8) -> 3245145 | R9: =SUM(R2:R8) -> 3405603 | T9: =SUM(T2:T8) -> 2202855.7 | U9: =SUM(U2:U8) -> 2016972.1

Sheet Januari Per Hari
A1: CABANG | B1: JUMLAH PELANGGAN DESEMBER 2024 | C1: JUMLAH PELANGGAN BULAN JANUARI | D1: PENDAPATAN AIR BULAN DESEMBER 2024 | E1: PENDAPATAN AIR BULAN JANUARI | F1: SELISIH PENDAPATAN | G1: PRESENTASE PENDAPATAN | H1: KONSUMSI GOL 2 BULAN DESEMBER 2024 | I1: KONSUMSI GOL 2 BULAN JANUARI | J1: KONSUMSI TOTAL BULAN DESEMBER 2024 | K1: KONSUMSI TOTAL BULAN JANUARI | L1: PRESENTASE KONSUMSI | M1: AIR DISTRIBUSI BULAN DESEMBER 2024 | N1: AIR DISTRIBUSI BULAN JANUARI | O1: SELISIH AIR DISTRIBUSI | P1: PRESENTASE SELISIH AIR DISTRIBUSI | Q1: AIR TERJUAL BULAN DESEMBER 2024 | R1: AIR TERJUAL BULAN JANUARI | S1: SELISIH AIR TERJUAL | T1: TKA BULAN DESEMBER 2024 | U1: TKA BULAN JANUARI | V1: PRESETASE TKA BULAN JANUARI | W1: PRESENTASE TKA BULAN FEBRUARI
A2: SIDOARJO | B2: 46406 | C2: 46450 | D2: =Januari!D2/31 -> 2.4738299e+08 | E2: =Januari!E2/31 -> 2.4980884e+08 | F2: =E2-D2 -> 2425842 | G2: =F2/D2 -> 0.0098060175 | H2: =Januari!H2/31 -> 21681.871 | I2: =Januari!I2/31 -> 22299.452 | J2: =Januari!J2/31 -> 28543.161 | K2: =Januari!K2/31 -> 28748.226 | L2: =K2/J2 -> 1.0071844 | M2: 1460240.4 | N2: 1461926.9 | O2: =N2-M2 -> 1686.4667 | P2: =O2/M2 -> 0.001154924 | Q2: 884838 | R2: 891195 | S2: =R2-Q2 -> 6357 | T2: =M2-Q2 -> 575402.41 | U2: =N2-R2 -> 570731.88 | V2: =T2/M2 -> 0.39404635 | W2: =U2/N2 -> 0.39039701
A3: GEDANGAN | B3: 34520 | C3: 34769 | D3: =Januari!D3/31 -> 1.6415364e+08 | E3: =Januari!E3/31 -> 1.7550584e+08 | F3: =E3-D3 -> 11352198 | G3: =F3/D3 -> 0.069155934 | H3: =Januari!H3/31 -> 14428.516 | I3: =Januari!I3/31 -> 15706.935 | J3: =Januari!J3/31 -> 18698 | K3: =Januari!K3/31 -> 19873.548 | L3: =K3/J3 -> 1.0628703 | M3: 995788.89 | N3: 967330.04 | O3: =N3-M3 -> -28458.85 | P3: =O3/M3 -> -0.0285792 | Q3: 579638 | R3: 616080 | S3: =R3-Q3 -> 36442 | T3: =M3-Q3 -> 416150.89 | U3: =N3-R3 -> 351250.04 | V3: =T3/M3 -> 0.41791076 | W3: =U3/N3 -> 0.36311292
A4: TAMAN | B4: 33828 | C4: 33811 | D4: =Januari!D4/31 -> 1.4445074e+08 | E4: =Januari!E4/31 -> 1.5376448e+08 | F4: =E4-D4 -> 9313739.5 | G4: =F4/D4 -> 0.064476926 | H4: =Januari!H4/31 -> 18154.839 | I4: =Januari!I4/31 -> 19001.258 | J4: =Januari!J4/31 -> 20083.323 | K4: =Januari!K4/31 -> 21083.935 | L4: =K4/J4 -> 1.0498231 | M4: 1135411.6 | N4: 1161556 | O4: =N4-M4 -> 26144.41 | P4: =O4/M4 -> 0.023026373 | Q4: 622583 | R4: 653602 | S4: =R4-Q4 -> 31019 | T4: =M4-Q4 -> 512828.55 | U4: =N4-R4 -> 507953.96 | V4: =T4/M4 -> 0.45166755 | W4: =U4/N4 -> 0.43730477
A5: WARU 1 | B5: 28075 | C5: 28116 | D5: =Januari!D5/31 -> 1.2341913e+08 | E5: =Januari!E5/31 -> 1.2998181e+08 | F5: =E5-D5 -> 6562682.8 | G5: =F5/D5 -> 0.053173951 | H5: =Januari!H5/31 -> 12710.742 | I5: =Januari!I5/31 -> 12885.258 | J5: =Januari!J5/31 -> 15017.774 | K5: =Januari!K5/31 -> 15433.484 | L5: =K5/J5 -> 1.0276812 | M5: 842911 | N5: 758750.78 | O5: =N5-M5 -> -84160.222 | P5: =O5/M5 -> -0.099844731 | Q5: 465551 | R5: 478438 | S5: =R5-Q5 -> 12887 | T5: =M5-Q5 -> 377360 | U5: =N5-R5 -> 280312.78 | V5: =T5/M5 -> 0.44768665 | W5: =U5/N5 -> 0.36943986
A6: WARU 2 | B6: 21208 | C6: 21216 | D6: =Januari!D6/31 -> 98534319 | E6: =Januari!E6/31 -> 1.0444726e+08 | F6: =E6-D6 -> 5912942.6 | G6: =F6/D6 -> 0.060008966 | H6: =Januari!H6/31 -> 10915.548 | I6: =Januari!I6/31 -> 11398.516 | J6: =Januari!J6/31 -> 12557.484 | K6: =Januari!K6/31 -> 13087.355 | L6: =K6/J6 -> 1.0421956 | M6: 490952.2 | N6: 573968.82 | O6: =N6-M6 -> 83016.622 | P6: =O6/M6 -> 0.16909309 | Q6: 389282 | R6: 405708 | S6: =R6-Q6 -> 16426 | T6: =M6-Q6 -> 101670.2 | U6: =N6-R6 -> 168260.82 | V6: =T6/M6 -> 0.20708778 | W6: =U6/N6 -> 0.29315324
A7: PORONG | B7: 15809 | C7: 15780 | D7: =Januari!D7/31 -> 58616616 | E7: =Januari!E7/31 -> 72368103 | F7: =E7-D7 -> 13751487 | G7: =F7/D7 -> 0.23460049 | H7: =Januari!H7/31 -> 5691 | I7: =Januari!I7/31 -> 6414.3871 | J7: =Januari!J7/31 -> 7089.2258 | K7: =Januari!K7/31 -> 8351.4839 | L7: =K7/J7 -> 1.178053 | M7: 384051.68 | N7: 362813.01 | O7: =N7-M7 -> -21238.667 | P7: =O7/M7 -> -0.055301585 | Q7: 219766 | R7: 258896 | S7: =R7-Q7 -> 39130 | T7: =M7-Q7 -> 164285.68 | U7: =N7-R7 -> 103917.01 | V7: =T7/M7 -> 0.42776972 | W7: =U7/N7 -> 0.2864203
A8: KRIAN | B8: 6502 | C8: 6486 | D8: =Januari!D8/31 -> 19630458 | E8: =Januari!E8/31 -> 24358060 | F8: =E8-D8 -> 4727601.6 | G8: =F8/D8 -> 0.24082992 | H8: =Januari!H8/31 -> 2478.4516 | I8: =Januari!I8/31 -> 3000.129 | J8: =Januari!J8/31 -> 2693.129 | K8: =Januari!K8/31 -> 3280.129 | L8: =K8/J8 -> 1.2179621 | M8: 138644.95 | N8: 136229.65 | O8: =N8-M8 -> -2415.3 | P8: =O8/M8 -> -0.017420757 | Q8: 83487 | R8: 101684 | S8: =R8-Q8 -> 18197 | T8: =M8-Q8 -> 55157.95 | U8: =N8-R8 -> 34545.65 | V8: =T8/M8 -> 0.39783598 | W8: =U8/N8 -> 0.25358393
A9: TOTAL | B9: =SUM(B2:B8) -> 186348 | C9: =SUM(C2:C8) -> 186628 | D9: =SUM(D2:D8) -> 8.5618789e+08 | E9: =SUM(E2:E8) -> 9.1023439e+08 | H9: =SUM(H2:H8) -> 86060.968 | I9: =SUM(I2:I8) -> 90705.935 | J9: =SUM(J2:J8) -> 104682.1 | K9: =SUM(K2:K8) -> 109858.16 | M9: =SUM(M2:M8) -> 5448000.7 | N9: =SUM(N2:N8) -> 5422575.1 | Q9: =SUM(Q2:Q8) -> 3245145 | R9: =SUM(R2:R8) -> 3405603 | T9: =SUM(T2:T8) -> 2202855.7 | U9: =SUM(U2:U8) -> 2016972.1

Sheet Februari
A1: CABANG | B1: JUMLAH PELANGGAN JANUARI | C1: JUMLAH PELANGGAN BULAN FEBRUARI | D1: PENDAPATAN AIR BULAN JANUARI | E1: PENDAPATAN AIR BULAN FEBRUARI | F1: SELISIH PENDAPATAN | G1: PRESENTASE PENDAPATAN | H1: KONSUMSI GOL 2 BULAN JANUARI | I1: KONSUMSI GOL 2 BULAN FEBRUARI | J1: KONSUMSI TOTAL BULAN JANUARI | K1: KONSUMSI TOTAL BULAN FEBRUARI | L1: PRESENTASE KONSUMSI | M1: AIR DISTRIBUSI BULAN JANUARI | N1: AIR DISTRIBUSI BULAN FEBRUARI | O1: SELISIH AIR DISTRIBUSI | P1: PRESENTASE SELISIH AIR DISTRIBUSI | Q1: AIR TERJUAL BULAN JANUARI | R1: AIR TERJUAL BULAN FEBRUARI | S1: SELISIH AIR TERJUAL | T1: TKA BULAN JANUARI | U1: TKA BULAN FEBRUARI | V1: PRESETASE TKA BULAN JANUARI | W1: PRESENTASE TKA BULAN FEBRUARI
A2: SIDOARJO | B2: 46450 | C2: 46603 | D2: 7744073901 | E2: 7748180087 | F2: =E2-D2 -> 4106186 | G2: =F2/D2 -> 0.0005302359 | H2: 691283 | I2: 670064 | J2: 891195 | K2: 877850 | L2: =K2/J2 -> 0.98502572 | M2: 1460240.4 | N2: 1461926.9 | O2: =N2-M2 -> 1686.4667 | P2: =O2/M2 -> 0.001154924 | Q2: 891195 | R2: 877850 | S2: =R2-Q2 -> -13345 | T2: =M2-Q2 -> 569045.41 | U2: =N2-R2 -> 584076.88 | V2: =T2/M2 -> 0.38969296 | W2: =U2/N2 -> 0.39952537
A3: GEDANGAN | B3: 34769 | C3: 34789 | D3: 5440680942 | E3: 5315742535 | F3: =E3-D3 -> -124938407 | G3: =F3/D3 -> -0.022963744 | H3: 486915 | I3: 466574 | J3: 616080 | K3: 596861 | L3: =K3/J3 -> 0.96880438 | M3: 995788.89 | N3: 967330.04 | O3: =N3-M3 -> -28458.85 | P3: =O3/M3 -> -0.0285792 | Q3: 616080 | R3: 596861 | S3: =R3-Q3 -> -19219 | T3: =M3-Q3 -> 379708.89 | U3: =N3-R3 -> 370469.04 | V3: =T3/M3 -> 0.38131465 | W3: =U3/N3 -> 0.38298101
A4: TAMAN | B4: 33811 | C4: 33801 | D4: 4766698773 | E4: 4678544910 | F4: =E4-D4 -> -88153863 | G4: =F4/D4 -> -0.018493693 | H4: 589039 | I4: 568340 | J4: 653602 | K4: 639148 | L4: =K4/J4 -> 0.97788562 | M4: 1135411.6 | N4: 1161556 | O4: =N4-M4 -> 26144.41 | P4: =O4/M4 -> 0.023026373 | Q4: 653602 | R4: 639148 | S4: =R4-Q4 -> -14454 | T4: =M4-Q4 -> 481809.55 | U4: =N4-R4 -> 522407.96 | V4: =T4/M4 -> 0.42434794 | W4: =U4/N4 -> 0.44974842
A5: WARU 1 | B5: 28116 | C5: 28145 | D5: 4029436166 | E5: 4011795930 | F5: =E5-D5 -> -17640236 | G5: =F5/D5 -> -0.0043778423 | H5: 399443 | I5: 403464 | J5: 478438 | K5: 480344 | L5: =K5/J5 -> 1.0039838 | M5: 842911 | N5: 758750.78 | O5: =N5-M5 -> -84160.222 | P5: =O5/M5 -> -0.099844731 | Q5: 478438 | R5: 480344 | S5: =R5-Q5 -> 1906 | T5: =M5-Q5 -> 364473 | U5: =N5-R5 -> 278406.78 | V5: =T5/M5 -> 0.43239796 | W5: =U5/N5 -> 0.36692783
A6: WARU 2 | B6: 21216 | C6: 21231 | D6: 3237865121 | E6: 3218841457 | F6: =E6-D6 -> -19023664 | G6: =F6/D6 -> -0.0058753726 | H6: 353354 | I6: 348012 | J6: 405708 | K6: 400994 | L6: =K6/J6 -> 0.98838081 | M6: 490952.2 | N6: 573968.82 | O6: =N6-M6 -> 83016.622 | P6: =O6/M6 -> 0.16909309 | Q6: 405708 | R6: 400994 | S6: =R6-Q6 -> -4714 | T6: =M6-Q6 -> 85244.2 | U6: =N6-R6 -> 172974.82 | V6: =T6/M6 -> 0.17363035 | W6: =U6/N6 -> 0.30136623
A7: PORONG | B7: 15780 | C7: 15794 | D7: 2243411191 | E7: 2124402253 | F7: =E7-D7 -> -119008938 | G7: =F7/D7 -> -0.053048206 | H7: 198846 | I7: 181449 | J7: 258896 | K7: 241796 | L7: =K7/J7 -> 0.93395031 | M7: 384051.68 | N7: 362813.01 | O7: =N7-M7 -> -21238.667 | P7: =O7/M7 -> -0.055301585 | Q7: 258896 | R7: 241796 | S7: =R7-Q7 -> -17100 | T7: =M7-Q7 -> 125155.68 | U7: =N7-R7 -> 121017.01 | V7: =T7/M7 -> 0.32588239 | W7: =U7/N7 -> 0.33355202
A8: KRIAN | B8: 6486 | C8: 6497 | D8: 755099850 | E8: 726581461 | F8: =E8-D8 -> -28518389 | G8: =F8/D8 -> -0.037767706 | H8: 93004 | I8: 88263 | J8: 101684 | K8: 97606 | L8: =K8/J8 -> 0.95989536 | M8: 138644.95 | N8: 136229.65 | O8: =N8-M8 -> -2415.3 | P8: =O8/M8 -> -0.017420757 | Q8: 101684 | R8: 97606 | S8: =R8-Q8 -> -4078 | T8: =M8-Q8 -> 36960.95 | U8: =N8-R8 -> 38623.65 | V8: =T8/M8 -> 0.26658706 | W8: =U8/N8 -> 0.28351868
A9: TOTAL | B9: =SUM(B2:B8) -> 186628 | C9: =SUM(C2:C8) -> 186860 | D9: =SUM(D2:D8) -> 28217265944 | E9: =SUM(E2:E8) -> 27824088633 | H9: =SUM(H2:H8) -> 2811884 | I9: =SUM(I2:I8) -> 2726166 | J9: =SUM(J2:J8) -> 3405603 | K9: =SUM(K2:K8) -> 3334599 | M9: =SUM(M2:M8)+3665 -> 5451665.7 | N9: =SUM(N2:N8)+4953 -> 5427528.1 | Q9: =SUM(Q2:Q8) -> 3405603 | R9: =SUM(R2:R8) -> 3334599 | T9: =SUM(T2:T8) -> 2042397.7 | U9: =SUM(U2:U8) -> 2087976.1

Sheet Februari Per Hari 
A1: CABANG | B1: JUMLAH PELANGGAN JANUARI | C1: JUMLAH PELANGGAN BULAN FEBRUARI | D1: PENDAPATAN AIR BULAN JANUARI | E1: PENDAPATAN AIR BULAN FEBRUARI | F1: SELISIH PENDAPATAN | G1: PRESENTASE PENDAPATAN | H1: KONSUMSI GOL 2 BULAN JANUARI | I1: KONSUMSI GOL 2 BULAN FEBRUARI | J1: KONSUMSI TOTAL BULAN JANUARI | K1: KONSUMSI TOTAL BULAN FEBRUARI | L1: PRESENTASE KONSUMSI | M1: AIR DISTRIBUSI BULAN JANUARI | N1: AIR DISTRIBUSI BULAN FEBRUARI | O1: SELISIH AIR DISTRIBUSI | P1: PRESENTASE SELISIH AIR DISTRIBUSI | Q1: AIR TERJUAL BULAN JANUARI | R1: AIR TERJUAL BULAN FEBRUARI | S1: SELISIH AIR TERJUAL | T1: TKA BULAN JANUARI | U1: TKA BULAN FEBRUARI | V1: PRESETASE TKA BULAN JANUARI | W1: PRESENTASE TKA BULAN FEBRUARI
A2: SIDOARJO | B2: 46450 | C2: 46603 | D2: =Februari!D2/31 -> 2.4980884e+08 | E2: =Februari!E2/28 -> 2.7672072e+08 | F2: =E2-D2 -> 26911882 | G2: =F2/D2 -> 0.1077299 | H2: =Februari!H2/31 -> 22299.452 | I2: =Februari!I2/28 -> 23930.857 | J2: =Februari!J2/31 -> 28748.226 | K2: =Februari!K2/28 -> 31351.786 | L2: =K2/J2 -> 1.0905642 | M2: =Februari!M2/31 -> 47104.529 | N2: =Februari!N2/28 -> 52211.674 | O2: =N2-M2 -> 5107.1448 | P2: =O2/M2 -> 0.10842152 | Q2: =Februari!Q2/31 -> 28748.226 | R2: =Februari!R2/28 -> 31351.786 | S2: =R2-Q2 -> 2603.5599 | T2: =M2-Q2 -> 18356.304 | U2: =N2-R2 -> 20859.888 | V2: =T2/M2 -> 0.38969296 | W2: =U2/N2 -> 0.39952537
A3: GEDANGAN | B3: 34769 | C3: 34789 | D3: =Februari!D3/31 -> 1.7550584e+08 | E3: =Februari!E3/28 -> 1.8984795e+08 | F3: =E3-D3 -> 14342111 | G3: =F3/D3 -> 0.081718711 | H3: =Februari!H3/31 -> 15706.935 | I3: =Februari!I3/28 -> 16663.357 | J3: =Februari!J3/31 -> 19873.548 | K3: =Februari!K3/28 -> 21316.464 | L3: =K3/J3 -> 1.0726048 | M3: =Februari!M3/31 -> 32122.222 | N3: =Februari!N3/28 -> 34547.501 | O3: =N3-M3 -> 2425.2792 | P3: =O3/M3 -> 0.0755016 | Q3: =Februari!Q3/31 -> 19873.548 | R3: =Februari!R3/28 -> 21316.464 | S3: =R3-Q3 -> 1442.9159 | T3: =M3-Q3 -> 12248.674 | U3: =N3-R3 -> 13231.037 | V3: =T3/M3 -> 0.38131465 | W3: =U3/N3 -> 0.38298101
A4: TAMAN | B4: 33811 | C4: 33801 | D4: =Februari!D4/31 -> 1.5376448e+08 | E4: =Februari!E4/28 -> 1.6709089e+08 | F4: =E4-D4 -> 13326413 | G4: =F4/D4 -> 0.086667697 | H4: =Februari!H4/31 -> 19001.258 | I4: =Februari!I4/28 -> 20297.857 | J4: =Februari!J4/31 -> 21083.935 | K4: =Februari!K4/28 -> 22826.714 | L4: =K4/J4 -> 1.0826591 | M4: =Februari!M4/31 -> 36626.179 | N4: =Februari!N4/28 -> 41484.141 | O4: =N4-M4 -> 4857.9624 | P4: =O4/M4 -> 0.13263634 | Q4: =Februari!Q4/31 -> 21083.935 | R4: =Februari!R4/28 -> 22826.714 | S4: =R4-Q4 -> 1742.7788 | T4: =M4-Q4 -> 15542.244 | U4: =N4-R4 -> 18657.427 | V4: =T4/M4 -> 0.42434794 | W4: =U4/N4 -> 0.44974842
A5: WARU 1 | B5: 28116 | C5: 28145 | D5: =Februari!D5/31 -> 1.2998181e+08 | E5: =Februari!E5/28 -> 1.4327843e+08 | F5: =E5-D5 -> 13296614 | G5: =F5/D5 -> 0.10229596 | H5: =Februari!H5/31 -> 12885.258 | I5: =Februari!I5/28 -> 14409.429 | J5: =Februari!J5/31 -> 15433.484 | K5: =Februari!K5/28 -> 17155.143 | L5: =K5/J5 -> 1.1115535 | M5: =Februari!M5/31 -> 27190.677 | N5: =Februari!N5/28 -> 27098.242 | O5: =N5-M5 -> -92.435356 | P5: =O5/M5 -> -0.0033995238 | Q5: =Februari!Q5/31 -> 15433.484 | R5: =Februari!R5/28 -> 17155.143 | S5: =R5-Q5 -> 1721.659 | T5: =M5-Q5 -> 11757.194 | U5: =N5-R5 -> 9943.0992 | V5: =T5/M5 -> 0.43239796 | W5: =U5/N5 -> 0.36692783
A6: WARU 2 | B6: 21216 | C6: 21231 | D6: =Februari!D6/31 -> 1.0444726e+08 | E6: =Februari!E6/28 -> 1.1495862e+08 | F6: =E6-D6 -> 10511361 | G6: =F6/D6 -> 0.10063798 | H6: =Februari!H6/31 -> 11398.516 | I6: =Februari!I6/28 -> 12429 | J6: =Februari!J6/31 -> 13087.355 | K6: =Februari!K6/28 -> 14321.214 | L6: =K6/J6 -> 1.0942787 | M6: =Februari!M6/31 -> 15837.168 | N6: =Februari!N6/28 -> 20498.887 | O6: =N6-M6 -> 4661.7188 | P6: =O6/M6 -> 0.29435306 | Q6: =Februari!Q6/31 -> 13087.355 | R6: =Februari!R6/28 -> 14321.214 | S6: =R6-Q6 -> 1233.8594 | T6: =M6-Q6 -> 2749.8129 | U6: =N6-R6 -> 6177.6722 | V6: =T6/M6 -> 0.17363035 | W6: =U6/N6 -> 0.30136623
A7: PORONG | B7: 15780 | C7: 15794 | D7: =Februari!D7/31 -> 72368103 | E7: =Februari!E7/28 -> 75871509 | F7: =E7-D7 -> 3503406.1 | G7: =F7/D7 -> 0.048410915 | H7: =Februari!H7/31 -> 6414.3871 | I7: =Februari!I7/28 -> 6480.3214 | J7: =Februari!J7/31 -> 8351.4839 | K7: =Februari!K7/28 -> 8635.5714 | L7: =K7/J7 -> 1.0340164 | M7: =Februari!M7/31 -> 12388.764 | N7: =Februari!N7/28 -> 12957.608 | O7: =N7-M7 -> 568.84375 | P7: =O7/M7 -> 0.045916102 | Q7: =Februari!Q7/31 -> 8351.4839 | R7: =Februari!R7/28 -> 8635.5714 | S7: =R7-Q7 -> 284.08756 | T7: =M7-Q7 -> 4037.28 | U7: =N7-R7 -> 4322.0362 | V7: =T7/M7 -> 0.32588239 | W7: =U7/N7 -> 0.33355202
A8: KRIAN | B8: 6486 | C8: 6497 | D8: =Februari!D8/31 -> 24358060 | E8: =Februari!E8/28 -> 25949338 | F8: =E8-D8 -> 1591278.2 | G8: =F8/D8 -> 0.065328611 | H8: =Februari!H8/31 -> 3000.129 | I8: =Februari!I8/28 -> 3152.25 | J8: =Februari!J8/31 -> 3280.129 | K8: =Februari!K8/28 -> 3485.9286 | L8: =K8/J8 -> 1.0627413 | M8: =Februari!M8/31 -> 4472.4177 | N8: =Februari!N8/28 -> 4865.3446 | O8: =N8-M8 -> 392.9269 | P8: =O8/M8 -> 0.08785559 | Q8: =Februari!Q8/31 -> 3280.129 | R8: =Februari!R8/28 -> 3485.9286 | S8: =R8-Q8 -> 205.79954 | T8: =M8-Q8 -> 1192.2887 | U8: =N8-R8 -> 1379.4161 | V8: =T8/M8 -> 0.26658706 | W8: =U8/N8 -> 0.28351868
A9: TOTAL | B9: =SUM(B2:B8) -> 186628 | C9: =SUM(C2:C8) -> 186860 | D9: =SUM(D2:D8) -> 9.1023439e+08 | E9: =SUM(E2:E8) -> 9.9371745e+08 | H9: =SUM(H2:H8) -> 90705.935 | I9: =SUM(I2:I8) -> 97363.071 | J9: =SUM(J2:J8) -> 109858.16 | K9: =SUM(K2:K8) -> 119092.82 | M9: =SUM(M2:M8)+3665 -> 179406.96 | N9: =SUM(N2:N8)+4953 -> 198616.4 | Q9: =SUM(Q2:Q8)+2839 -> 112697.16 | R9: =SUM(R2:R8)+2841 -> 121933.82 | T9: =SUM(T2:T8)+826 -> 66709.796 | U9: =SUM(U2:U8)+2112 -> 76682.576 | V9: =SUM(M9-Q9)/M9 -> 0.37183506 | W9: =SUM(N9-R9)/N9 -> 0.38608381

Sheet Maret
A1: CABANG | B1: JUMLAH PELANGGAN FEBRUARI | C1: JUMLAH PELANGGAN BULAN MARET | D1: PENDAPATAN AIR BULAN FEBRUARI | E1: PENDAPATAN AIR BULAN MARET | F1: SELISIH PENDAPATAN | G1: PRESENTASE PENDAPATAN | H1: KONSUMSI GOL 2 BULAN FEBRUARI | I1: KONSUMSI GOL 2 BULAN MARET | J1: KONSUMSI TOTAL BULAN FEBRUARI | K1: KONSUMSI TOTAL BULAN MARET | L1: PRESENTASE KONSUMSI | M1: AIR DISTRIBUSI BULAN FEBRUARI | N1: AIR DISTRIBUSI BULAN MARET | O1: SELISIH AIR DISTRIBUSI | P1: PRESENTASE SELISIH AIR DISTRIBUSI | Q1: AIR TERJUAL BULAN FEBRUARI | R1: AIR TERJUAL BULAN MARET | S1: SELISIH AIR TERJUAL | T1: TKA BULAN FEBRUARI | U1: TKA BULAN MARET | V1: PRESETASE TKA BULAN FEBRUARI | W1: PRESENTASE TKA BULAN MARET
A2: SIDOARJO | B2: 46603 | C2: 46627 | D2: 7748180087 | E2: 6983417956 | F2: =E2-D2 -> -764762131 | G2: =F2/D2 -> -0.098702163 | H2: 670064 | I2: 609136 | J2: 877850 | K2: 792606 | L2: =K2/J2 -> 0.90289457 | M2: 1461926.9 | N2: 1267967.7 | O2: =N2-M2 -> -193959.2 | P2: =O2/M2 -> -0.13267367 | Q2: 877850 | R2: 792606 | S2: =R2-Q2 -> -85244 | T2: =M2-Q2 -> 584076.88 | U2: =N2-R2 -> 475361.68 | V2: =T2/M2 -> 0.39952537 | W2: =U2/N2 -> 0.37490047
A3: GEDANGAN | B3: 34789 | C3: 34985 | D3: 5315742535 | E3: 4830758887 | F3: =E3-D3 -> -484983648 | G3: =F3/D3 -> -0.091235353 | H3: 466574 | I3: 423647 | J3: 596861 | K3: 542455 | L3: =K3/J3 -> 0.90884645 | M3: 967330.04 | N3: 891487.04 | O3: =N3-M3 -> -75843 | P3: =O3/M3 -> -0.078404471 | Q3: 596861 | R3: 542455 | S3: =R3-Q3 -> -54406 | T3: =M3-Q3 -> 370469.04 | U3: =N3-R3 -> 349032.04 | V3: =T3/M3 -> 0.38298101 | W3: =U3/N3 -> 0.39151667
A4: TAMAN | B4: 33801 | C4: 33791 | D4: 4678544910 | E4: 4287192017 | F4: =E4-D4 -> -391352893 | G4: =F4/D4 -> -0.083648421 | H4: 568340 | I4: 526218 | J4: 639148 | K4: 591222 | L4: =K4/J4 -> 0.9250158 | M4: 1161556 | N4: 971630.33 | O4: =N4-M4 -> -189925.63 | P4: =O4/M4 -> -0.16350967 | Q4: 639148 | R4: 591222 | S4: =R4-Q4 -> -47926 | T4: =M4-Q4 -> 522407.96 | U4: =N4-R4 -> 380408.33 | V4: =T4/M4 -> 0.44974842 | W4: =U4/N4 -> 0.3915155
A5: WARU 1 | B5: 28145 | C5: 28175 | D5: 4011795930 | E5: 3725166353 | F5: =E5-D5 -> -286629577 | G5: =F5/D5 -> -0.071446699 | H5: 403464 | I5: 381723 | J5: 480344 | K5: 452823 | L5: =K5/J5 -> 0.94270564 | M5: 758750.78 | N5: 727952.78 | O5: =N5-M5 -> -30798 | P5: =O5/M5 -> -0.040590403 | Q5: 480344 | R5: 452823 | S5: =R5-Q5 -> -27521 | T5: =M5-Q5 -> 278406.78 | U5: =N5-R5 -> 275129.78 | V5: =T5/M5 -> 0.36692783 | W5: =U5/N5 -> 0.37795003
A6: WARU 2 | B6: 21231 | C6: 21225 | D6: 3218841457 | E6: 2915896545 | F6: =E6-D6 -> -302944912 | G6: =F6/D6 -> -0.094116133 | H6: 348012 | I6: 320778 | J6: 400994 | K6: 366890 | L6: =K6/J6 -> 0.91495135 | M6: 573968.82 | N6: 573365.32 | O6: =N6-M6 -> -603.5 | P6: =O6/M6 -> -0.0010514508 | Q6: 400994 | R6: 366890 | S6: =R6-Q6 -> -34104 | T6: =M6-Q6 -> 172974.82 | U6: =N6-R6 -> 206475.32 | V6: =T6/M6 -> 0.30136623 | W6: =U6/N6 -> 0.36011128
A7: PORONG | B7: 15794 | C7: 15772 | D7: 2124402253 | E7: 2225023116 | F7: =E7-D7 -> 100620863 | G7: =F7/D7 -> 0.047364318 | H7: 181449 | I7: 174551 | J7: 241796 | K7: 243936 | L7: =K7/J7 -> 1.0088504 | M7: 362813.01 | N7: 361481.36 | O7: =N7-M7 -> -1331.65 | P7: =O7/M7 -> -0.003670348 | Q7: 241796 | R7: 243936 | S7: =R7-Q7 -> 2140 | T7: =M7-Q7 -> 121017.01 | U7: =N7-R7 -> 117545.36 | V7: =T7/M7 -> 0.33355202 | W7: =U7/N7 -> 0.32517683
A8: KRIAN | B8: 6497 | C8: 6501 | D8: 726581461 | E8: 650725421 | F8: =E8-D8 -> -75856040 | G8: =F8/D8 -> -0.10440129 | H8: 88263 | I8: 80624 | J8: 97606 | K8: 88273 | L8: =K8/J8 -> 0.90438088 | M8: 136229.65 | N8: 158787.65 | O8: =N8-M8 -> 22558 | P8: =O8/M8 -> 0.16558803 | Q8: 97606 | R8: 88273 | S8: =R8-Q8 -> -9333 | T8: =M8-Q8 -> 38623.65 | U8: =N8-R8 -> 70514.65 | V8: =T8/M8 -> 0.28351868 | W8: =U8/N8 -> 0.44408145
A9: TOTAL | B9: =SUM(B2:B8) -> 186860 | C9: =SUM(C2:C8) -> 187076 | D9: =SUM(D2:D8) -> 27824088633 | E9: =SUM(E2:E8) -> 25618180295 | H9: =SUM(H2:H8) -> 2726166 | I9: =SUM(I2:I8) -> 2516677 | J9: =SUM(J2:J8) -> 3334599 | K9: =SUM(K2:K8) -> 3078205 | M9: =SUM(M2:M8)+4953 -> 5427528.1 | N9: =SUM(N2:N8)+12767 -> 4965439.2 | Q9: =SUM(Q2:Q8)+2841 -> 3337440 | R9: =SUM(R2:R8)+2548 -> 3080753 | T9: =SUM(T2:T8)+2112 -> 2090088.1 | U9: =SUM(U2:U8)+10219 -> 1884686.2 | V9: =SUM(M9-Q9)/M9 -> 0.38509024 | W9: =SUM(N9-R9)/N9 -> 0.37956082

Sheet Maret Per Hari
A1: CABANG | B1: JUMLAH PELANGGAN FEBRUARI | C1: JUMLAH PELANGGAN BULAN MARET | D1: PENDAPATAN AIR BULAN FEBRUARI | E1: PENDAPATAN AIR BULAN MARET | F1: SELISIH PENDAPATAN | G1: PRESENTASE PENDAPATAN | H1: KONSUMSI GOL 2 BULAN FEBRUARI | I1: KONSUMSI GOL 2 BULAN MARET | J1: KONSUMSI TOTAL BULAN FEBRUARI | K1: KONSUMSI TOTAL BULAN MARET | L1: PRESENTASE KONSUMSI | M1: AIR DISTRIBUSI BULAN FEBRUARI | N1: AIR DISTRIBUSI BULAN MARET | O1: SELISIH AIR DISTRIBUSI | P1: PRESENTASE SELISIH AIR DISTRIBUSI | Q1: AIR TERJUAL BULAN FEBRUARI | R1: AIR TERJUAL BULAN MARET | S1: SELISIH AIR TERJUAL | T1: TKA BULAN FEBRUARI | U1: TKA BULAN MARET | V1: PRESETASE TKA BULAN FEBRUARI | W1: PRESENTASE TKA BULAN MARET
A2: SIDOARJO | B2: 46603 | C2: 46627 | D2: =Maret!D2/28 -> 2.7672072e+08 | E2: =Maret!E2/31 -> 2.2527155e+08 | F2: =E2-D2 -> -51449170 | G2: =F2/D2 -> -0.18592453 | H2: =Maret!H2/28 -> 23930.857 | I2: =Maret!I2/31 -> 19649.548 | J2: =Maret!J2/28 -> 31351.786 | K2: =Maret!K2/31 -> 25567.935 | L2: =K2/J2 -> 0.81551768 | M2: =Maret!M2/28 -> 52211.674 | N2: =Maret!N2/31 -> 40902.183 | O2: =N2-M2 -> -11309.491 | P2: =O2/M2 -> -0.21660847 | Q2: =Maret!Q2/28 -> 31351.786 | R2: =Maret!R2/31 -> 25567.935 | S2: =R2-Q2 -> -5783.8502 | T2: =M2-Q2 -> 20859.888 | U2: =N2-R2 -> 15334.248 | V2: =T2/M2 -> 0.39952537 | W2: =U2/N2 -> 0.37490047
A3: GEDANGAN | B3: 34789 | C3: 34985 | D3: =Maret!D3/28 -> 1.8984795e+08 | E3: =Maret!E3/31 -> 1.5583093e+08 | F3: =E3-D3 -> -34017016 | G3: =F3/D3 -> -0.17918032 | H3: =Maret!H3/28 -> 16663.357 | I3: =Maret!I3/31 -> 13666.032 | J3: =Maret!J3/28 -> 21316.464 | K3: =Maret!K3/31 -> 17498.548 | L3: =K3/J3 -> 0.82089357 | M3: =Maret!M3/28 -> 34547.501 | N3: =Maret!N3/31 -> 28757.646 | O3: =N3-M3 -> -5789.855 | P3: =O3/M3 -> -0.16759114 | Q3: =Maret!Q3/28 -> 21316.464 | R3: =Maret!R3/31 -> 17498.548 | S3: =R3-Q3 -> -3817.9159 | T3: =M3-Q3 -> 13231.037 | U3: =N3-R3 -> 11259.098 | V3: =T3/M3 -> 0.38298101 | W3: =U3/N3 -> 0.39151667
A4: TAMAN | B4: 33801 | C4: 33791 | D4: =Maret!D4/28 -> 1.6709089e+08 | E4: =Maret!E4/31 -> 1.3829652e+08 | F4: =E4-D4 -> -28794373 | G4: =F4/D4 -> -0.17232761 | H4: =Maret!H4/28 -> 20297.857 | I4: =Maret!I4/31 -> 16974.774 | J4: =Maret!J4/28 -> 22826.714 | K4: =Maret!K4/31 -> 19071.677 | L4: =K4/J4 -> 0.83549814 | M4: =Maret!M4/28 -> 41484.141 | N4: =Maret!N4/31 -> 31342.914 | O4: =N4-M4 -> -10141.228 | P4: =O4/M4 -> -0.24446035 | Q4: =Maret!Q4/28 -> 22826.714 | R4: =Maret!R4/31 -> 19071.677 | S4: =R4-Q4 -> -3755.0369 | T4: =M4-Q4 -> 18657.427 | U4: =N4-R4 -> 12271.236 | V4: =T4/M4 -> 0.44974842 | W4: =U4/N4 -> 0.3915155
A5: WARU 1 | B5: 28145 | C5: 28175 | D5: =Maret!D5/28 -> 1.4327843e+08 | E5: =Maret!E5/31 -> 1.2016666e+08 | F5: =E5-D5 -> -23111770 | G5: =F5/D5 -> -0.1613067 | H5: =Maret!H5/28 -> 14409.429 | I5: =Maret!I5/31 -> 12313.645 | J5: =Maret!J5/28 -> 17155.143 | K5: =Maret!K5/31 -> 14607.194 | L5: =K5/J5 -> 0.85147607 | M5: =Maret!M5/28 -> 27098.242 | N5: =Maret!N5/31 -> 23482.348 | O5: =N5-M5 -> -3615.8944 | P5: =O5/M5 -> -0.13343649 | Q5: =Maret!Q5/28 -> 17155.143 | R5: =Maret!R5/31 -> 14607.194 | S5: =R5-Q5 -> -2547.9493 | T5: =M5-Q5 -> 9943.0992 | U5: =N5-R5 -> 8875.1541 | V5: =T5/M5 -> 0.36692783 | W5: =U5/N5 -> 0.37795003
A6: WARU 2 | B6: 21231 | C6: 21225 | D6: =Maret!D6/28 -> 1.1495862e+08 | E6: =Maret!E6/31 -> 94061179 | F6: =E6-D6 -> -20897445 | G6: =F6/D6 -> -0.18178231 | H6: =Maret!H6/28 -> 12429 | I6: =Maret!I6/31 -> 10347.677 | J6: =Maret!J6/28 -> 14321.214 | K6: =Maret!K6/31 -> 11835.161 | L6: =K6/J6 -> 0.82640767 | M6: =Maret!M6/28 -> 20498.887 | N6: =Maret!N6/31 -> 18495.656 | O6: =N6-M6 -> -2003.231 | P6: =O6/M6 -> -0.097723891 | Q6: =Maret!Q6/28 -> 14321.214 | R6: =Maret!R6/31 -> 11835.161 | S6: =R6-Q6 -> -2486.053 | T6: =M6-Q6 -> 6177.6722 | U6: =N6-R6 -> 6660.4943 | V6: =T6/M6 -> 0.30136623 | W6: =U6/N6 -> 0.36011128
A7: PORONG | B7: 15794 | C7: 15772 | D7: =Maret!D7/28 -> 75871509 | E7: =Maret!E7/31 -> 71774939 | F7: =E7-D7 -> -4096569.8 | G7: =F7/D7 -> -0.05399352 | H7: =Maret!H7/28 -> 6480.3214 | I7: =Maret!I7/31 -> 5630.6774 | J7: =Maret!J7/28 -> 8635.5714 | K7: =Maret!K7/31 -> 7868.9032 | L7: =K7/J7 -> 0.91121975 | M7: =Maret!M7/28 -> 12957.608 | N7: =Maret!N7/31 -> 11660.689 | O7: =N7-M7 -> -1296.9185 | P7: =O7/M7 -> -0.10008935 | Q7: =Maret!Q7/28 -> 8635.5714 | R7: =Maret!R7/31 -> 7868.9032 | S7: =R7-Q7 -> -766.6682 | T7: =M7-Q7 -> 4322.0362 | U7: =N7-R7 -> 3791.7859 | V7: =T7/M7 -> 0.33355202 | W7: =U7/N7 -> 0.32517683
A8: KRIAN | B8: 6497 | C8: 6501 | D8: =Maret!D8/28 -> 25949338 | E8: =Maret!E8/31 -> 20991143 | F8: =E8-D8 -> -4958195.3 | G8: =F8/D8 -> -0.19107213 | H8: =Maret!H8/28 -> 3152.25 | I8: =Maret!I8/31 -> 2600.7742 | J8: =Maret!J8/28 -> 3485.9286 | K8: =Maret!K8/31 -> 2847.5161 | L8: =K8/J8 -> 0.81686015 | M8: =Maret!M8/28 -> 4865.3446 | N8: =Maret!N8/31 -> 5122.1823 | O8: =N8-M8 -> 256.83762 | P8: =O8/M8 -> 0.052789193 | Q8: =Maret!Q8/28 -> 3485.9286 | R8: =Maret!R8/31 -> 2847.5161 | S8: =R8-Q8 -> -638.41244 | T8: =M8-Q8 -> 1379.4161 | U8: =N8-R8 -> 2274.6661 | V8: =T8/M8 -> 0.28351868 | W8: =U8/N8 -> 0.44408145
A9: TOTAL | B9: =SUM(B2:B8) -> 186860 | C9: =SUM(C2:C8) -> 187076 | D9: =SUM(D2:D8) -> 9.9371745e+08 | E9: =SUM(E2:E8) -> 8.2639291e+08 | H9: =SUM(H2:H8) -> 97363.071 | I9: =SUM(I2:I8) -> 81183.129 | J9: =SUM(J2:J8) -> 119092.82 | K9: =SUM(K2:K8) -> 99296.935 | M9: =SUM(M2:M8)+4953 -> 198616.4 | N9: =SUM(N2:N8)+12767 -> 172530.62 | Q9: =SUM(Q2:Q8)+2841 -> 121933.82 | R9: =SUM(R2:R8)+2548 -> 101844.94 | T9: =SUM(T2:T8)+2112 -> 76682.576 | U9: =SUM(U2:U8)+10219 -> 70685.683 | V9: =SUM(M9-Q9)/M9 -> 0.38608381 | W9: =SUM(N9-R9)/N9 -> 0.40969935

Sheet April
A1: CABANG | B1: JUMLAH PELANGGAN MARET | C1: JUMLAH PELANGGAN BULAN APRIL | D1: PENDAPATAN AIR BULAN MARET | E1: PENDAPATAN AIR BULAN APRIL | F1: SELISIH PENDAPATAN | G1: PRESENTASE PENDAPATAN | H1: KONSUMSI GOL 2 BULAN MARET | I1: KONSUMSI GOL 2 BULAN APRIL | J1: KONSUMSI TOTAL BULAN MARET | K1: KONSUMSI TOTAL BULAN APRIL | L1: PRESENTASE KONSUMSI | M1: AIR DISTRIBUSI BULAN MARET | N1: AIR DISTRIBUSI BULAN APRIL | O1: SELISIH AIR DISTRIBUSI | P1: PRESENTASE SELISIH AIR DISTRIBUSI | Q1: AIR TERJUAL BULAN MARET | R1: AIR TERJUAL BULAN APRIL | S1: SELISIH AIR TERJUAL | T1: TKA BULAN MARET | U1: TKA BULAN APRIL | V1: PRESETASE TKA BULAN MARET | W1: PRESENTASE TKA BULAN APRIL
A2: SIDOARJO | B2: 46627 | C2: 46607 | D2: 6983417956 | E2: 8094458788 | F2: =E2-D2 -> 1111040832 | G2: =F2/D2 -> 0.159097 | H2: 609136 | I2: 730077 | J2: 792606 | K2: 927222 | L2: =K2/J2 -> 1.1698397 | M2: 1267967.7 | N2: 1408521.1 | O2: =N2-M2 -> 140553.42 | P2: =O2/M2 -> 0.11084937 | Q2: 792606 | R2: 927222 | S2: =R2-Q2 -> 134616 | T2: =M2-Q2 -> 475361.68 | U2: =N2-R2 -> 481299.1 | V2: =T2/M2 -> 0.37490047 | W2: =U2/N2 -> 0.34170528
A3: GEDANGAN | B3: 34985 | C3: 35147 | D3: 4830758887 | E3: 5325961222 | F3: =E3-D3 -> 495202335 | G3: =F3/D3 -> 0.10251026 | H3: 423647 | I3: 495364 | J3: 542455 | K3: 612461 | L3: =K3/J3 -> 1.129054 | M3: 891487.04 | N3: 965826.62 | O3: =N3-M3 -> 74339.584 | P3: =O3/M3 -> 0.083388295 | Q3: 542455 | R3: 612461 | S3: =R3-Q3 -> 70006 | T3: =M3-Q3 -> 349032.04 | U3: =N3-R3 -> 353365.62 | V3: =T3/M3 -> 0.39151667 | W3: =U3/N3 -> 0.36586859
A4: TAMAN | B4: 33791 | C4: 33788 | D4: 4287192017 | E4: 4953941466 | F4: =E4-D4 -> 666749449 | G4: =F4/D4 -> 0.15552125 | H4: 526218 | I4: 613680 | J4: 591222 | K4: 680245 | L4: =K4/J4 -> 1.1505746 | M4: 971630.33 | N4: 1092523.3 | O4: =N4-M4 -> 120892.99 | P4: =O4/M4 -> 0.12442282 | Q4: 591222 | R4: 680245 | S4: =R4-Q4 -> 89023 | T4: =M4-Q4 -> 380408.33 | U4: =N4-R4 -> 412278.32 | V4: =T4/M4 -> 0.3915155 | W4: =U4/N4 -> 0.3773634
A5: WARU 1 | B5: 28175 | C5: 28186 | D5: 3725166353 | E5: 4211219746 | F5: =E5-D5 -> 486053393 | G5: =F5/D5 -> 0.13047831 | H5: 381723 | I5: 429672 | J5: 452823 | K5: 508741 | L5: =K5/J5 -> 1.1234875 | M5: 727952.78 | N5: 760428.78 | O5: =N5-M5 -> 32476 | P5: =O5/M5 -> 0.044612784 | Q5: 452823 | R5: 508741 | S5: =R5-Q5 -> 55918 | T5: =M5-Q5 -> 275129.78 | U5: =N5-R5 -> 251687.78 | V5: =T5/M5 -> 0.37795003 | W5: =U5/N5 -> 0.3309814
A6: WARU 2 | B6: 21225 | C6: 21221 | D6: 2915896545 | E6: 3282380791 | F6: =E6-D6 -> 366484246 | G6: =F6/D6 -> 0.12568493 | H6: 320778 | I6: 359714 | J6: 366890 | K6: 410565 | L6: =K6/J6 -> 1.1190411 | M6: 573365.32 | N6: 560088.74 | O6: =N6-M6 -> -13276.58 | P6: =O6/M6 -> -0.023155534 | Q6: 366890 | R6: 410565 | S6: =R6-Q6 -> 43675 | T6: =M6-Q6 -> 206475.32 | U6: =N6-R6 -> 149523.74 | V6: =T6/M6 -> 0.36011128 | W6: =U6/N6 -> 0.26696438
A7: PORONG | B7: 15772 | C7: 15754 | D7: 2225023116 | E7: 2350518561 | F7: =E7-D7 -> 125495445 | G7: =F7/D7 -> 0.056401861 | H7: 174551 | I7: 218148 | J7: 243936 | K7: 274487 | L7: =K7/J7 -> 1.1252419 | M7: 361481.36 | N7: 456318.14 | O7: =N7-M7 -> 94836.78 | P7: =O7/M7 -> 0.26235593 | Q7: 243936 | R7: 274487 | S7: =R7-Q7 -> 30551 | T7: =M7-Q7 -> 117545.36 | U7: =N7-R7 -> 181831.14 | V7: =T7/M7 -> 0.32517683 | W7: =U7/N7 -> 0.3984745
A8: KRIAN | B8: 6501 | C8: 6496 | D8: 650725421 | E8: 774162276 | F8: =E8-D8 -> 123436855 | G8: =F8/D8 -> 0.18969115 | H8: 80624 | I8: 94991 | J8: 88273 | K8: 104568 | L8: =K8/J8 -> 1.1845978 | M8: 158787.65 | N8: 183413.41 | O8: =N8-M8 -> 24625.76 | P8: =O8/M8 -> 0.15508612 | Q8: 88273 | R8: 104568 | S8: =R8-Q8 -> 16295 | T8: =M8-Q8 -> 70514.65 | U8: =N8-R8 -> 78845.41 | V8: =T8/M8 -> 0.44408145 | W8: =U8/N8 -> 0.42987811
A9: TOTAL | B9: =SUM(B2:B8) -> 187076 | C9: =SUM(C2:C8) -> 187199 | D9: =SUM(D2:D8) -> 25618180295 | E9: =SUM(E2:E8) -> 28992642850 | H9: =SUM(H2:H8) -> 2516677 | I9: =SUM(I2:I8) -> 2941646 | J9: =SUM(J2:J8) -> 3078205 | K9: =SUM(K2:K8) -> 3518289 | M9: =SUM(M2:M8)+12767 -> 4965439.2 | N9: =SUM(N2:N8)+12133 -> 5439253.1 | Q9: =SUM(Q2:Q8)+2548 -> 3080753 | R9: =SUM(R2:R8)+2542 -> 3520831 | T9: =SUM(T2:T8)+10219 -> 1884686.2 | U9: =SUM(U2:U8)+9591 -> 1918422.1 | V9: =SUM(M9-Q9)/M9 -> 0.37956082 | W9: =SUM(N9-R9)/N9 -> 0.35269955

Sheet April Per Hari
A1: CABANG | B1: JUMLAH PELANGGAN MARET | C1: JUMLAH PELANGGAN BULAN APRIL | D1: PENDAPATAN AIR BULAN MARET | E1: PENDAPATAN AIR BULAN APRIL | F1: SELISIH PENDAPATAN | G1: PRESENTASE PENDAPATAN | H1: KONSUMSI GOL 2 BULAN MARET | I1: KONSUMSI GOL 2 BULAN APRIL | J1: KONSUMSI TOTAL BULAN MARET | K1: KONSUMSI TOTAL BULAN APRIL | L1: PRESENTASE KONSUMSI | M1: AIR DISTRIBUSI BULAN MARET | N1: AIR DISTRIBUSI BULAN APRIL | O1: SELISIH AIR DISTRIBUSI | P1: PRESENTASE SELISIH AIR DISTRIBUSI | Q1: AIR TERJUAL BULAN MARET | R1: AIR TERJUAL BULAN APRIL | S1: SELISIH AIR TERJUAL | T1: TKA BULAN MARET | U1: TKA BULAN APRIL | V1: PRESETASE TKA BULAN MARET | W1: PRESENTASE TKA BULAN APRIL
A2: SIDOARJO | B2: 46627 | C2: 46607 | D2: =April!D2/31 -> 2.2527155e+08 | E2: =April!E2/30 -> 2.6981529e+08 | F2: =E2-D2 -> 44543746 | G2: =F2/D2 -> 0.19773356 | H2: =April!H2/31 -> 19649.548 | I2: =April!I2/30 -> 24335.9 | J2: =April!J2/31 -> 25567.935 | K2: =April!K2/30 -> 30907.4 | L2: =K2/J2 -> 1.2088344 | M2: =April!M2/31 -> 40902.183 | N2: =April!N2/30 -> 46950.703 | O2: =N2-M2 -> 6048.5201 | P2: =O2/M2 -> 0.14787768 | Q2: =April!Q2/31 -> 25567.935 | R2: =April!R2/30 -> 30907.4 | S2: =R2-Q2 -> 5339.4645 | T2: =M2-Q2 -> 15334.248 | U2: =N2-R2 -> 16043.303 | V2: =T2/M2 -> 0.37490047 | W2: =U2/N2 -> 0.34170528
A3: GEDANGAN | B3: 34985 | C3: 35147 | D3: =April!D3/31 -> 1.5583093e+08 | E3: =April!E3/30 -> 1.7753204e+08 | F3: =E3-D3 -> 21701109 | G3: =F3/D3 -> 0.1392606 | H3: =April!H3/31 -> 13666.032 | I3: =April!I3/30 -> 16512.133 | J3: =April!J3/31 -> 17498.548 | K3: =April!K3/30 -> 20415.367 | L3: =K3/J3 -> 1.1666892 | M3: =April!M3/31 -> 28757.646 | N3: =April!N3/30 -> 32194.221 | O3: =N3-M3 -> 3436.5743 | P3: =O3/M3 -> 0.11950124 | Q3: =April!Q3/31 -> 17498.548 | R3: =April!R3/30 -> 20415.367 | S3: =R3-Q3 -> 2916.8183 | T3: =M3-Q3 -> 11259.098 | U3: =N3-R3 -> 11778.854 | V3: =T3/M3 -> 0.39151667 | W3: =U3/N3 -> 0.36586859
A4: TAMAN | B4: 33791 | C4: 33788 | D4: =April!D4/31 -> 1.3829652e+08 | E4: =April!E4/30 -> 1.6513138e+08 | F4: =E4-D4 -> 26834866 | G4: =F4/D4 -> 0.19403862 | H4: =April!H4/31 -> 16974.774 | I4: =April!I4/30 -> 20456 | J4: =April!J4/31 -> 19071.677 | K4: =April!K4/30 -> 22674.833 | L4: =K4/J4 -> 1.1889271 | M4: =April!M4/31 -> 31342.914 | N4: =April!N4/30 -> 36417.444 | O4: =N4-M4 -> 5074.53 | P4: =O4/M4 -> 0.16190358 | Q4: =April!Q4/31 -> 19071.677 | R4: =April!R4/30 -> 22674.833 | S4: =R4-Q4 -> 3603.1559 | T4: =M4-Q4 -> 12271.236 | U4: =N4-R4 -> 13742.611 | V4: =T4/M4 -> 0.3915155 | W4: =U4/N4 -> 0.3773634
A5: WARU 1 | B5: 28175 | C5: 28186 | D5: =April!D5/31 -> 1.2016666e+08 | E5: =April!E5/30 -> 1.4037399e+08 | F5: =E5-D5 -> 20207335 | G5: =F5/D5 -> 0.16816092 | H5: =April!H5/31 -> 12313.645 | I5: =April!I5/30 -> 14322.4 | J5: =April!J5/31 -> 14607.194 | K5: =April!K5/30 -> 16958.033 | L5: =K5/J5 -> 1.1609371 | M5: =April!M5/31 -> 23482.348 | N5: =April!N5/30 -> 25347.626 | O5: =N5-M5 -> 1865.2783 | P5: =O5/M5 -> 0.07943321 | Q5: =April!Q5/31 -> 14607.194 | R5: =April!R5/30 -> 16958.033 | S5: =R5-Q5 -> 2350.8398 | T5: =M5-Q5 -> 8875.1541 | U5: =N5-R5 -> 8389.5926 | V5: =T5/M5 -> 0.37795003 | W5: =U5/N5 -> 0.3309814
A6: WARU 2 | B6: 21225 | C6: 21221 | D6: =April!D6/31 -> 94061179 | E6: =April!E6/30 -> 1.0941269e+08 | F6: =E6-D6 -> 15351514 | G6: =F6/D6 -> 0.16320776 | H6: =April!H6/31 -> 10347.677 | I6: =April!I6/30 -> 11990.467 | J6: =April!J6/31 -> 11835.161 | K6: =April!K6/30 -> 13685.5 | L6: =K6/J6 -> 1.1563425 | M6: =April!M6/31 -> 18495.656 | N6: =April!N6/30 -> 18669.625 | O6: =N6-M6 -> 173.96919 | P6: =O6/M6 -> 0.0094059486 | Q6: =April!Q6/31 -> 11835.161 | R6: =April!R6/30 -> 13685.5 | S6: =R6-Q6 -> 1850.3387 | T6: =M6-Q6 -> 6660.4943 | U6: =N6-R6 -> 4984.1247 | V6: =T6/M6 -> 0.36011128 | W6: =U6/N6 -> 0.26696438
A7: PORONG | B7: 15772 | C7: 15754 | D7: =April!D7/31 -> 71774939 | E7: =April!E7/30 -> 78350619 | F7: =E7-D7 -> 6575679.5 | G7: =F7/D7 -> 0.091615257 | H7: =April!H7/31 -> 5630.6774 | I7: =April!I7/30 -> 7271.6 | J7: =April!J7/31 -> 7868.9032 | K7: =April!K7/30 -> 9149.5667 | L7: =K7/J7 -> 1.1627499 | M7: =April!M7/31 -> 11660.689 | N7: =April!N7/30 -> 15210.605 | O7: =N7-M7 -> 3549.9156 | P7: =O7/M7 -> 0.30443446 | Q7: =April!Q7/31 -> 7868.9032 | R7: =April!R7/30 -> 9149.5667 | S7: =R7-Q7 -> 1280.6634 | T7: =M7-Q7 -> 3791.7859 | U7: =N7-R7 -> 6061.0381 | V7: =T7/M7 -> 0.32517683 | W7: =U7/N7 -> 0.3984745
A8: KRIAN | B8: 6501 | C8: 6496 | D8: =April!D8/31 -> 20991143 | E8: =April!E8/30 -> 25805409 | F8: =E8-D8 -> 4814266.6 | G8: =F8/D8 -> 0.22934752 | H8: =April!H8/31 -> 2600.7742 | I8: =April!I8/30 -> 3166.3667 | J8: =April!J8/31 -> 2847.5161 | K8: =April!K8/30 -> 3485.6 | L8: =K8/J8 -> 1.2240844 | M8: =April!M8/31 -> 5122.1823 | N8: =April!N8/30 -> 6113.7803 | O8: =N8-M8 -> 991.59808 | P8: =O8/M8 -> 0.19358899 | Q8: =April!Q8/31 -> 2847.5161 | R8: =April!R8/30 -> 3485.6 | S8: =R8-Q8 -> 638.08387 | T8: =M8-Q8 -> 2274.6661 | U8: =N8-R8 -> 2628.1803 | V8: =T8/M8 -> 0.44408145 | W8: =U8/N8 -> 0.42987811
A9: TOTAL | B9: =SUM(B2:B8) -> 187076 | C9: =SUM(C2:C8) -> 187199 | D9: =SUM(D2:D8) -> 8.2639291e+08 | E9: =SUM(E2:E8) -> 9.6642143e+08 | H9: =SUM(H2:H8) -> 81183.129 | I9: =SUM(I2:I8) -> 98054.867 | J9: =SUM(J2:J8) -> 99296.935 | K9: =SUM(K2:K8) -> 117276.3 | M9: =SUM(M2:M8)+12767 -> 172530.62 | N9: =SUM(N2:N8)+12133 -> 193037 | Q9: =SUM(Q2:Q8)+2548 -> 101844.94 | R9: =SUM(R2:R8)+2542 -> 119818.3 | T9: =SUM(T2:T8)+10219 -> 70685.683 | U9: =SUM(U2:U8)+9591 -> 73218.704 | V9: =SUM(M9-Q9)/M9 -> 0.40969935 | W9: =SUM(N9-R9)/N9 -> 0.3792988

Sheet Mei
A1: CABANG | B1: JUMLAH PELANGGAN APRIL | C1: JUMLAH PELANGGAN BULAN MEI | D1: PENDAPATAN AIR BULAN APRIL | E1: PENDAPATAN AIR BULAN MEI | F1: SELISIH PENDAPATAN | G1: PRESENTASE PENDAPATAN | H1: KONSUMSI GOL 2 BULAN APRIL | I1: KONSUMSI GOL 2 BULAN MEI | J1: KONSUMSI TOTAL BULAN APRIL | K1: KONSUMSI TOTAL BULAN MEI | L1: PRESENTASE KONSUMSI | M1: AIR DISTRIBUSI BULAN APRIL | N1: AIR DISTRIBUSI BULAN MEI | O1: SELISIH AIR DISTRIBUSI | P1: PRESENTASE SELISIH AIR DISTRIBUSI | Q1: AIR TERJUAL BULAN APRIL | R1: AIR TERJUAL BULAN MEI | S1: SELISIH AIR TERJUAL | T1: TKA BULAN APRIL | U1: TKA BULAN MEI | V1: PRESETASE TKA BULAN APRIL | W1: PRESENTASE TKA BULAN MEI
A2: SIDOARJO | B2: 46607 | C2: 46677 | D2: 8094458788 | E2: 7290373130 | F2: =E2-D2 -> -804085658 | G2: =F2/D2 -> -0.099337791 | H2: 730077 | I2: 653261 | J2: 927222 | K2: 834522 | L2: =K2/J2 -> 0.90002394 | M2: 1408521.1 | N2: 1466285.5 | O2: =N2-M2 -> 57764.44 | P2: =O2/M2 -> 0.041010703 | Q2: 927222 | R2: 834522 | S2: =R2-Q2 -> -92700 | T2: =M2-Q2 -> 481299.1 | U2: =N2-R2 -> 631763.54 | V2: =T2/M2 -> 0.34170528 | W2: =U2/N2 -> 0.43085983
A3: GEDANGAN | B3: 35147 | C3: 35174 | D3: 5325961222 | E3: 4975497888 | F3: =E3-D3 -> -350463334 | G3: =F3/D3 -> -0.065802832 | H3: 495364 | I3: 456030 | J3: 612461 | K3: 571175 | L3: =K3/J3 -> 0.93258999 | M3: 965826.62 | N3: 856542.51 | O3: =N3-M3 -> -109284.11 | P3: =O3/M3 -> -0.11315086 | Q3: 612461 | R3: 571175 | S3: =R3-Q3 -> -41286 | T3: =M3-Q3 -> 353365.62 | U3: =N3-R3 -> 285367.51 | V3: =T3/M3 -> 0.36586859 | W3: =U3/N3 -> 0.33316211
A4: TAMAN | B4: 33788 | C4: 33764 | D4: 4953941466 | E4: 4152375286 | F4: =E4-D4 -> -801566180 | G4: =F4/D4 -> -0.16180372 | H4: 613680 | I4: 513064 | J4: 680245 | K4: 574527 | L4: =K4/J4 -> 0.84458835 | M4: 1092523.3 | N4: 1036985.3 | O4: =N4-M4 -> -55537.986 | P4: =O4/M4 -> -0.0508346 | Q4: 680245 | R4: 574527 | S4: =R4-Q4 -> -105718 | T4: =M4-Q4 -> 412278.32 | U4: =N4-R4 -> 462458.33 | V4: =T4/M4 -> 0.3773634 | W4: =U4/N4 -> 0.4459642
A5: WARU 1 | B5: 28186 | C5: 28176 | D5: 4211219746 | E5: 3826372670 | F5: =E5-D5 -> -384847076 | G5: =F5/D5 -> -0.09138613 | H5: 429672 | I5: 391205 | J5: 508741 | K5: 462867 | L5: =K5/J5 -> 0.90982838 | M5: 760428.78 | N5: 740041.78 | O5: =N5-M5 -> -20387 | P5: =O5/M5 -> -0.026809874 | Q5: 508741 | R5: 462867 | S5: =R5-Q5 -> -45874 | T5: =M5-Q5 -> 251687.78 | U5: =N5-R5 -> 277174.78 | V5: =T5/M5 -> 0.3309814 | W5: =U5/N5 -> 0.37453937
A6: WARU 2 | B6: 21221 | C6: 21244 | D6: 3282380791 | E6: 3028764979 | F6: =E6-D6 -> -253615812 | G6: =F6/D6 -> -0.07726581 | H6: 359714 | I6: 334596 | J6: 410565 | K6: 381219 | L6: =K6/J6 -> 0.92852289 | M6: 560088.74 | N6: 560458.52 | O6: =N6-M6 -> 369.78 | P6: =O6/M6 -> 0.00066021681 | Q6: 410565 | R6: 381219 | S6: =R6-Q6 -> -29346 | T6: =M6-Q6 -> 149523.74 | U6: =N6-R6 -> 179239.52 | V6: =T6/M6 -> 0.26696438 | W6: =U6/N6 -> 0.31980872
A7: PORONG | B7: 15754 | C7: 15758 | D7: 2350518561 | E7: 2095454696 | F7: =E7-D7 -> -255063865 | G7: =F7/D7 -> -0.10851387 | H7: 218148 | I7: 191129 | J7: 274487 | K7: 243761 | L7: =K7/J7 -> 0.88806027 | M7: 456318.14 | N7: 472211.81 | O7: =N7-M7 -> 15893.67 | P7: =O7/M7 -> 0.034830239 | Q7: 274487 | R7: 243761 | S7: =R7-Q7 -> -30726 | T7: =M7-Q7 -> 181831.14 | U7: =N7-R7 -> 228450.81 | V7: =T7/M7 -> 0.3984745 | W7: =U7/N7 -> 0.48378886
A8: KRIAN | B8: 6496 | C8: 6499 | D8: 774162276 | E8: 686788013 | F8: =E8-D8 -> -87374263 | G8: =F8/D8 -> -0.11286298 | H8: 94991 | I8: 83978 | J8: 104568 | K8: 93298 | L8: =K8/J8 -> 0.89222324 | M8: 183413.41 | N8: 172886.65 | O8: =N8-M8 -> -10526.76 | P8: =O8/M8 -> -0.057393622 | Q8: 104568 | R8: 93298 | S8: =R8-Q8 -> -11270 | T8: =M8-Q8 -> 78845.41 | U8: =N8-R8 -> 79588.65 | V8: =T8/M8 -> 0.42987811 | W8: =U8/N8 -> 0.46035162
A9: TOTAL | B9: =SUM(B2:B8) -> 187199 | C9: =SUM(C2:C8) -> 187292 | D9: =SUM(D2:D8) -> 28992642850 | E9: =SUM(E2:E8) -> 26055626662 | H9: =SUM(H2:H8) -> 2941646 | I9: =SUM(I2:I8) -> 2623263 | J9: =SUM(J2:J8) -> 3518289 | K9: =SUM(K2:K8) -> 3161369 | M9: =SUM(M2:M8)+12133 -> 5439253.1 | N9: =SUM(N2:N8)+2472 -> 5307884.1 | Q9: =SUM(Q2:Q8)+2542 -> 3520831 | R9: =SUM(R2:R8)+2129 -> 3163498 | T9: =SUM(T2:T8)+9591 -> 1918422.1 | U9: =SUM(U2:U8)+343 -> 2144386.1 | V9: =SUM(M9-Q9)/M9 -> 0.35269955 | W9: =SUM(N9-R9)/N9 -> 0.40400018

Sheet Mei Per Hari
A1: CABANG | B1: JUMLAH PELANGGAN APRIL | C1: JUMLAH PELANGGAN BULAN MEI | D1: PENDAPATAN AIR BULAN APRIL | E1: PENDAPATAN AIR BULAN MEI | F1: SELISIH PENDAPATAN | G1: PRESENTASE PENDAPATAN | H1: KONSUMSI GOL 2 BULAN APRIL | I1: KONSUMSI GOL 2 BULAN MEI | J1: KONSUMSI TOTAL BULAN APRIL | K1: KONSUMSI TOTAL BULAN MEI | L1: PRESENTASE KONSUMSI | M1: AIR DISTRIBUSI BULAN APRIL | N1: AIR DISTRIBUSI BULAN MEI | O1: SELISIH AIR DISTRIBUSI | P1: PRESENTASE SELISIH AIR DISTRIBUSI | Q1: AIR TERJUAL BULAN APRIL | R1: AIR TERJUAL BULAN MEI | S1: SELISIH AIR TERJUAL | T1: TKA BULAN APRIL | U1: TKA BULAN MEI | V1: PRESETASE TKA BULAN APRIL | W1: PRESENTASE TKA BULAN MEI
A2: SIDOARJO | B2: 46607 | C2: 46677 | D2: =Mei!D2/30 -> 2.6981529e+08 | E2: =Mei!E2/31 -> 2.3517333e+08 | F2: =E2-D2 -> -34641966 | G2: =F2/D2 -> -0.12839141 | H2: =Mei!H2/30 -> 24335.9 | I2: =Mei!I2/31 -> 21072.935 | J2: =Mei!J2/30 -> 30907.4 | K2: =Mei!K2/31 -> 26920.065 | L2: =K2/J2 -> 0.87099091 | M2: =Mei!M2/30 -> 46950.703 | N2: =Mei!N2/31 -> 47299.533 | O2: =N2-M2 -> 348.83022 | P2: =O2/M2 -> 0.0074297123 | Q2: =Mei!Q2/30 -> 30907.4 | R2: =Mei!R2/31 -> 26920.065 | S2: =R2-Q2 -> -3987.3355 | T2: =M2-Q2 -> 16043.303 | U2: =N2-R2 -> 20379.469 | V2: =T2/M2 -> 0.34170528 | W2: =U2/N2 -> 0.43085983
A3: GEDANGAN | B3: 35147 | C3: 35174 | D3: =Mei!D3/30 -> 1.7753204e+08 | E3: =Mei!E3/31 -> 1.6049993e+08 | F3: =E3-D3 -> -17032109 | G3: =F3/D3 -> -0.095938225 | H3: =Mei!H3/30 -> 16512.133 | I3: =Mei!I3/31 -> 14710.645 | J3: =Mei!J3/30 -> 20415.367 | K3: =Mei!K3/31 -> 18425 | L3: =K3/J3 -> 0.90250645 | M3: =Mei!M3/30 -> 32194.221 | N3: =Mei!N3/31 -> 27630.404 | O3: =N3-M3 -> -4563.8173 | P3: =O3/M3 -> -0.1417589 | Q3: =Mei!Q3/30 -> 20415.367 | R3: =Mei!R3/31 -> 18425 | S3: =R3-Q3 -> -1990.3667 | T3: =M3-Q3 -> 11778.854 | U3: =N3-R3 -> 9205.4035 | V3: =T3/M3 -> 0.36586859 | W3: =U3/N3 -> 0.33316211
A4: TAMAN | B4: 33788 | C4: 33764 | D4: =Mei!D4/30 -> 1.6513138e+08 | E4: =Mei!E4/31 -> 1.3394759e+08 | F4: =E4-D4 -> -31183792 | G4: =F4/D4 -> -0.18884231 | H4: =Mei!H4/30 -> 20456 | I4: =Mei!I4/31 -> 16550.452 | J4: =Mei!J4/30 -> 22674.833 | K4: =Mei!K4/31 -> 18533.129 | L4: =K4/J4 -> 0.81734356 | M4: =Mei!M4/30 -> 36417.444 | N4: =Mei!N4/31 -> 33451.14 | O4: =N4-M4 -> -2966.3042 | P4: =O4/M4 -> -0.081452839 | Q4: =Mei!Q4/30 -> 22674.833 | R4: =Mei!R4/31 -> 18533.129 | S4: =R4-Q4 -> -4141.7043 | T4: =M4-Q4 -> 13742.611 | U4: =N4-R4 -> 14918.011 | V4: =T4/M4 -> 0.3773634 | W4: =U4/N4 -> 0.4459642
A5: WARU 1 | B5: 28186 | C5: 28176 | D5: =Mei!D5/30 -> 1.4037399e+08 | E5: =Mei!E5/31 -> 1.2343138e+08 | F5: =E5-D5 -> -16942615 | G5: =F5/D5 -> -0.12069626 | H5: =Mei!H5/30 -> 14322.4 | I5: =Mei!I5/31 -> 12619.516 | J5: =Mei!J5/30 -> 16958.033 | K5: =Mei!K5/31 -> 14931.194 | L5: =K5/J5 -> 0.88047908 | M5: =Mei!M5/30 -> 25347.626 | N5: =Mei!N5/31 -> 23872.315 | O5: =N5-M5 -> -1475.3105 | P5: =O5/M5 -> -0.058203104 | Q5: =Mei!Q5/30 -> 16958.033 | R5: =Mei!R5/31 -> 14931.194 | S5: =R5-Q5 -> -2026.8398 | T5: =M5-Q5 -> 8389.5926 | U5: =N5-R5 -> 8941.1219 | V5: =T5/M5 -> 0.3309814 | W5: =U5/N5 -> 0.37453937
A6: WARU 2 | B6: 21221 | C6: 21244 | D6: =Mei!D6/30 -> 1.0941269e+08 | E6: =Mei!E6/31 -> 97702096 | F6: =E6-D6 -> -11710597 | G6: =F6/D6 -> -0.10703143 | H6: =Mei!H6/30 -> 11990.467 | I6: =Mei!I6/31 -> 10793.419 | J6: =Mei!J6/30 -> 13685.5 | K6: =Mei!K6/31 -> 12297.387 | L6: =K6/J6 -> 0.89857054 | M6: =Mei!M6/30 -> 18669.625 | N6: =Mei!N6/31 -> 18079.307 | O6: =N6-M6 -> -590.31757 | P6: =O6/M6 -> -0.031619145 | Q6: =Mei!Q6/30 -> 13685.5 | R6: =Mei!R6/31 -> 12297.387 | S6: =R6-Q6 -> -1388.1129 | T6: =M6-Q6 -> 4984.1247 | U6: =N6-R6 -> 5781.9201 | V6: =T6/M6 -> 0.26696438 | W6: =U6/N6 -> 0.31980872
A7: PORONG | B7: 15754 | C7: 15758 | D7: =Mei!D7/30 -> 78350619 | E7: =Mei!E7/31 -> 67595313 | F7: =E7-D7 -> -10755306 | G7: =F7/D7 -> -0.13727149 | H7: =Mei!H7/30 -> 7271.6 | I7: =Mei!I7/31 -> 6165.4516 | J7: =Mei!J7/30 -> 9149.5667 | K7: =Mei!K7/31 -> 7863.2581 | L7: =K7/J7 -> 0.85941317 | M7: =Mei!M7/30 -> 15210.605 | N7: =Mei!N7/31 -> 15232.639 | O7: =N7-M7 -> 22.034362 | P7: =O7/M7 -> 0.0014486184 | Q7: =Mei!Q7/30 -> 9149.5667 | R7: =Mei!R7/31 -> 7863.2581 | S7: =R7-Q7 -> -1286.3086 | T7: =M7-Q7 -> 6061.0381 | U7: =N7-R7 -> 7369.3811 | V7: =T7/M7 -> 0.3984745 | W7: =U7/N7 -> 0.48378886
A8: KRIAN | B8: 6496 | C8: 6499 | D8: =Mei!D8/30 -> 25805409 | E8: =Mei!E8/31 -> 22154452 | F8: =E8-D8 -> -3650957.2 | G8: =F8/D8 -> -0.14148031 | H8: =Mei!H8/30 -> 3166.3667 | I8: =Mei!I8/31 -> 2708.9677 | J8: =Mei!J8/30 -> 3485.6 | K8: =Mei!K8/31 -> 3009.6129 | L8: =K8/J8 -> 0.86344185 | M8: =Mei!M8/30 -> 6113.7803 | N8: =Mei!N8/31 -> 5576.9887 | O8: =N8-M8 -> -536.79162 | P8: =O8/M8 -> -0.08780028 | Q8: =Mei!Q8/30 -> 3485.6 | R8: =Mei!R8/31 -> 3009.6129 | S8: =R8-Q8 -> -475.9871 | T8: =M8-Q8 -> 2628.1803 | U8: =N8-R8 -> 2567.3758 | V8: =T8/M8 -> 0.42987811 | W8: =U8/N8 -> 0.46035162
A9: TOTAL | B9: =SUM(B2:B8) -> 187199 | C9: =SUM(C2:C8) -> 187292 | D9: =SUM(D2:D8) -> 9.6642143e+08 | E9: =SUM(E2:E8) -> 8.4050409e+08 | H9: =SUM(H2:H8) -> 98054.867 | I9: =SUM(I2:I8) -> 84621.387 | J9: =SUM(J2:J8) -> 117276.3 | K9: =SUM(K2:K8) -> 101979.65 | M9: =SUM(M2:M8)+456318 -> 637222 | N9: =SUM(N2:N8)+472212 -> 643354.33 | Q9: =SUM(Q2:Q8)+274518 -> 391794.3 | R9: =SUM(R2:R8)+243761 -> 345740.65 | T9: =SUM(T2:T8)+9591 -> 73218.704 | U9: =SUM(U2:U8)+343 -> 69505.682 | V9: =SUM(M9-Q9)/M9 -> 0.38515259 | W9: =SUM(N9-R9)/N9 -> 0.46259685

Sheet Juni
A1: CABANG | B1: JUMLAH PELANGGAN MEI | C1: JUMLAH PELANGGAN BULAN JUNI | D1: PENDAPATAN AIR BULAN MEI | E1: PENDAPATAN AIR BULAN JUNI | F1: SELISIH PENDAPATAN | G1: PRESENTASE PENDAPATAN | H1: KONSUMSI GOL 2 BULAN MEI | I1: KONSUMSI GOL 2 BULAN JUNI | J1: KONSUMSI TOTAL BULAN MEI | K1: KONSUMSI TOTAL BULAN JUNI | L1: PRESENTASE KONSUMSI | M1: AIR DISTRIBUSI BULAN MEI | N1: AIR DISTRIBUSI BULAN JUNI | O1: SELISIH AIR DISTRIBUSI | P1: PRESENTASE SELISIH AIR DISTRIBUSI | Q1: AIR TERJUAL BULAN MEI | R1: AIR TERJUAL BULAN JUNI | S1: SELISIH AIR TERJUAL | T1: TKA BULAN MEI | U1: TKA BULAN JUNI | V1: PRESETASE TKA BULAN MEI | W1: PRESENTASE TKA BULAN JUNI
A2: SIDOARJO | B2: 46677 | C2: 46795 | D2: 7290373130 | E2: 7680966016 | F2: =E2-D2 -> 390592886 | G2: =F2/D2 -> 0.053576529 | H2: 653261 | I2: 691626 | J2: 834522 | K2: 883018 | L2: =K2/J2 -> 1.0581123 | M2: 1466285.5 | N2: 1489842.3 | O2: =N2-M2 -> 23556.733 | P2: =O2/M2 -> 0.016065584 | Q2: 834522 | R2: 883018 | S2: =R2-Q2 -> 48496 | T2: =M2-Q2 -> 631763.54 | U2: =N2-R2 -> 606824.27 | V2: =T2/M2 -> 0.43085983 | W2: =U2/N2 -> 0.40730773
A3: GEDANGAN | B3: 35174 | C3: 35355 | D3: 4975497888 | E3: 5399063040 | F3: =E3-D3 -> 423565152 | G3: =F3/D3 -> 0.085130204 | H3: 456030 | I3: 486671 | J3: 571175 | K3: 616495 | L3: =K3/J3 -> 1.0793452 | M3: 856542.51 | N3: 1024484.5 | O3: =N3-M3 -> 167942 | P3: =O3/M3 -> 0.19606966 | Q3: 571175 | R3: 616495 | S3: =R3-Q3 -> 45320 | T3: =M3-Q3 -> 285367.51 | U3: =N3-R3 -> 407989.51 | V3: =T3/M3 -> 0.33316211 | W3: =U3/N3 -> 0.39823883
A4: TAMAN | B4: 33764 | C4: 33771 | D4: 4152375286 | E4: 4456953081 | F4: =E4-D4 -> 304577795 | G4: =F4/D4 -> 0.073350257 | H4: 513064 | I4: 549075 | J4: 574527 | K4: 614079 | L4: =K4/J4 -> 1.0688427 | M4: 1036985.3 | N4: 953274.19 | O4: =N4-M4 -> -83711.14 | P4: =O4/M4 -> -0.080725481 | Q4: 574527 | R4: 614079 | S4: =R4-Q4 -> 39552 | T4: =M4-Q4 -> 462458.33 | U4: =N4-R4 -> 339195.19 | V4: =T4/M4 -> 0.4459642 | W4: =U4/N4 -> 0.35582122
A5: WARU 1 | B5: 28176 | C5: 28239 | D5: 3826372670 | E5: 4006767595 | F5: =E5-D5 -> 180394925 | G5: =F5/D5 -> 0.047145153 | H5: 391205 | I5: 411676 | J5: 462867 | K5: 485811 | L5: =K5/J5 -> 1.0495693 | M5: 740041.78 | N5: 763585.78 | O5: =N5-M5 -> 23544 | P5: =O5/M5 -> 0.03181442 | Q5: 462867 | R5: 485811 | S5: =R5-Q5 -> 22944 | T5: =M5-Q5 -> 277174.78 | U5: =N5-R5 -> 277774.78 | V5: =T5/M5 -> 0.37453937 | W5: =U5/N5 -> 0.36377678
A6: WARU 2 | B6: 21244 | C6: 21245 | D6: 3028764979 | E6: 3157121528 | F6: =E6-D6 -> 128356549 | G6: =F6/D6 -> 0.042379171 | H6: 334596 | I6: 336025 | J6: 381219 | K6: 390529 | L6: =K6/J6 -> 1.0244217 | M6: 560458.52 | N6: 686109.62 | O6: =N6-M6 -> 125651.1 | P6: =O6/M6 -> 0.2241934 | Q6: 381219 | R6: 390529 | S6: =R6-Q6 -> 9310 | T6: =M6-Q6 -> 179239.52 | U6: =N6-R6 -> 295580.62 | V6: =T6/M6 -> 0.31980872 | W6: =U6/N6 -> 0.4308067
A7: PORONG | B7: 15758 | C7: 15784 | D7: 2095454696 | E7: 2283769473 | F7: =E7-D7 -> 188314777 | G7: =F7/D7 -> 0.089868217 | H7: 191129 | I7: 194445 | J7: 243761 | K7: 257616 | L7: =K7/J7 -> 1.0568385 | M7: 472211.81 | N7: 440445.3 | O7: =N7-M7 -> -31766.513 | P7: =O7/M7 -> -0.067271746 | Q7: 243761 | R7: 257616 | S7: =R7-Q7 -> 13855 | T7: =M7-Q7 -> 228450.81 | U7: =N7-R7 -> 182829.3 | V7: =T7/M7 -> 0.48378886 | W7: =U7/N7 -> 0.41510104
A8: KRIAN | B8: 6499 | C8: 6511 | D8: 686788013 | E8: 715363470 | F8: =E8-D8 -> 28575457 | G8: =F8/D8 -> 0.04160739 | H8: 83978 | I8: 87806 | J8: 93298 | K8: 96382 | L8: =K8/J8 -> 1.0330554 | M8: 172886.65 | N8: 184340.65 | O8: =N8-M8 -> 11454 | P8: =O8/M8 -> 0.066251501 | Q8: 93298 | R8: 96382 | S8: =R8-Q8 -> 3084 | T8: =M8-Q8 -> 79588.65 | U8: =N8-R8 -> 87958.65 | V8: =T8/M8 -> 0.46035162 | W8: =U8/N8 -> 0.47715276
A9: TOTAL | B9: =SUM(B2:B8) -> 187292 | C9: =SUM(C2:C8) -> 187700 | D9: =SUM(D2:D8) -> 26055626662 | E9: =SUM(E2:E8) -> 27700004203 | H9: =SUM(H2:H8) -> 2623263 | I9: =SUM(I2:I8) -> 2757324 | J9: =SUM(J2:J8) -> 3161369 | K9: =SUM(K2:K8) -> 3343930 | M9: =SUM(M2:M8)+2472 -> 5307884.1 | N9: =SUM(N2:N8)+2427 -> 5544509.3 | Q9: =SUM(Q2:Q8)+2129 -> 3163498 | R9: =SUM(R2:R8)+2486 -> 3346416 | T9: =SUM(T2:T8)+343 -> 2144386.1 | U9: =SUM(U2:U8)+59 -> 2198211.3 | V9: =SUM(M9-Q9)/M9 -> 0.40400018 | W9: =SUM(N9-R9)/N9 -> 0.39644506

Sheet Juni Per Hari
A1: CABANG | B1: JUMLAH PELANGGAN MEI | C1: JUMLAH PELANGGAN BULAN JUNI | D1: PENDAPATAN AIR BULAN MEI | E1: PENDAPATAN AIR BULAN JUNI | F1: SELISIH PENDAPATAN | G1: PRESENTASE PENDAPATAN | H1: KONSUMSI GOL 2 BULAN MEI | I1: KONSUMSI GOL 2 BULAN JUNI | J1: KONSUMSI TOTAL BULAN MEI | K1: KONSUMSI TOTAL BULAN JUNI | L1: PRESENTASE KONSUMSI | M1: AIR DISTRIBUSI BULAN MEI | N1: AIR DISTRIBUSI BULAN JUNI | O1: SELISIH AIR DISTRIBUSI | P1: PRESENTASE SELISIH AIR DISTRIBUSI | Q1: AIR TERJUAL BULAN MEI | R1: AIR TERJUAL BULAN JUNI | S1: SELISIH AIR TERJUAL | T1: TKA BULAN MEI | U1: TKA BULAN JUNI | V1: PRESETASE TKA BULAN MEI | W1: PRESENTASE TKA BULAN JUNI
A2: SIDOARJO | B2: 46677 | C2: 46795 | D2: =Juni!D2/31 -> 2.3517333e+08 | E2: =Juni!E2/30 -> 2.560322e+08 | F2: =E2-D2 -> 20858874 | G2: =F2/D2 -> 0.088695746 | H2: =Juni!H2/31 -> 21072.935 | I2: =Juni!I2/30 -> 23054.2 | J2: =Juni!J2/31 -> 26920.065 | K2: =Juni!K2/30 -> 29433.933 | L2: =K2/J2 -> 1.0933827 | M2: =Juni!M2/31 -> 47299.533 | N2: =Juni!N2/30 -> 49661.409 | O2: =N2-M2 -> 2361.8756 | P2: =O2/M2 -> 0.049934437 | Q2: =Juni!Q2/31 -> 26920.065 | R2: =Juni!R2/30 -> 29433.933 | S2: =R2-Q2 -> 2513.8688 | T2: =M2-Q2 -> 20379.469 | U2: =N2-R2 -> 20227.476 | V2: =T2/M2 -> 0.43085983 | W2: =U2/N2 -> 0.40730773
A3: GEDANGAN | B3: 35174 | C3: 35355 | D3: =Juni!D3/31 -> 1.6049993e+08 | E3: =Juni!E3/30 -> 179968768 | F3: =E3-D3 -> 19468836 | G3: =F3/D3 -> 0.12130121 | H3: =Juni!H3/31 -> 14710.645 | I3: =Juni!I3/30 -> 16222.367 | J3: =Juni!J3/31 -> 18425 | K3: =Juni!K3/30 -> 20549.833 | L3: =K3/J3 -> 1.1153234 | M3: =Juni!M3/31 -> 27630.404 | N3: =Juni!N3/30 -> 34149.484 | O3: =N3-M3 -> 6519.0801 | P3: =O3/M3 -> 0.23593865 | Q3: =Juni!Q3/31 -> 18425 | R3: =Juni!R3/30 -> 20549.833 | S3: =R3-Q3 -> 2124.8333 | T3: =M3-Q3 -> 9205.4035 | U3: =N3-R3 -> 13599.65 | V3: =T3/M3 -> 0.33316211 | W3: =U3/N3 -> 0.39823883
A4: TAMAN | B4: 33764 | C4: 33771 | D4: =Juni!D4/31 -> 1.3394759e+08 | E4: =Juni!E4/30 -> 1.485651e+08 | F4: =E4-D4 -> 14617513 | G4: =F4/D4 -> 0.1091286 | H4: =Juni!H4/31 -> 16550.452 | I4: =Juni!I4/30 -> 18302.5 | J4: =Juni!J4/31 -> 18533.129 | K4: =Juni!K4/30 -> 20469.3 | L4: =K4/J4 -> 1.1044708 | M4: =Juni!M4/31 -> 33451.14 | N4: =Juni!N4/30 -> 31775.806 | O4: =N4-M4 -> -1675.3333 | P4: =O4/M4 -> -0.050082997 | Q4: =Juni!Q4/31 -> 18533.129 | R4: =Juni!R4/30 -> 20469.3 | S4: =R4-Q4 -> 1936.171 | T4: =M4-Q4 -> 14918.011 | U4: =N4-R4 -> 11306.506 | V4: =T4/M4 -> 0.4459642 | W4: =U4/N4 -> 0.35582122
A5: WARU 1 | B5: 28176 | C5: 28239 | D5: =Juni!D5/31 -> 1.2343138e+08 | E5: =Juni!E5/30 -> 1.3355892e+08 | F5: =E5-D5 -> 10127543 | G5: =F5/D5 -> 0.082049991 | H5: =Juni!H5/31 -> 12619.516 | I5: =Juni!I5/30 -> 13722.533 | J5: =Juni!J5/31 -> 14931.194 | K5: =Juni!K5/30 -> 16193.7 | L5: =K5/J5 -> 1.084555 | M5: =Juni!M5/31 -> 23872.315 | N5: =Juni!N5/30 -> 25452.859 | O5: =N5-M5 -> 1580.5438 | P5: =O5/M5 -> 0.066208234 | Q5: =Juni!Q5/31 -> 14931.194 | R5: =Juni!R5/30 -> 16193.7 | S5: =R5-Q5 -> 1262.5065 | T5: =M5-Q5 -> 8941.1219 | U5: =N5-R5 -> 9259.1593 | V5: =T5/M5 -> 0.37453937 | W5: =U5/N5 -> 0.36377678
A6: WARU 2 | B6: 21244 | C6: 21245 | D6: =Juni!D6/31 -> 97702096 | E6: =Juni!E6/30 -> 1.0523738e+08 | F6: =E6-D6 -> 7535288.2 | G6: =F6/D6 -> 0.077125143 | H6: =Juni!H6/31 -> 10793.419 | I6: =Juni!I6/30 -> 11200.833 | J6: =Juni!J6/31 -> 12297.387 | K6: =Juni!K6/30 -> 13017.633 | L6: =K6/J6 -> 1.058569 | M6: =Juni!M6/31 -> 18079.307 | N6: =Juni!N6/30 -> 22870.321 | O6: =N6-M6 -> 4791.0136 | P6: =O6/M6 -> 0.26499984 | Q6: =Juni!Q6/31 -> 12297.387 | R6: =Juni!R6/30 -> 13017.633 | S6: =R6-Q6 -> 720.24624 | T6: =M6-Q6 -> 5781.9201 | U6: =N6-R6 -> 9852.6874 | V6: =T6/M6 -> 0.31980872 | W6: =U6/N6 -> 0.4308067
A7: PORONG | B7: 15758 | C7: 15784 | D7: =Juni!D7/31 -> 67595313 | E7: =Juni!E7/30 -> 76125649 | F7: =E7-D7 -> 8530336.3 | G7: =F7/D7 -> 0.12619716 | H7: =Juni!H7/31 -> 6165.4516 | I7: =Juni!I7/30 -> 6481.5 | J7: =Juni!J7/31 -> 7863.2581 | K7: =Juni!K7/30 -> 8587.2 | L7: =K7/J7 -> 1.0920664 | M7: =Juni!M7/31 -> 15232.639 | N7: =Juni!N7/30 -> 14681.51 | O7: =N7-M7 -> -551.12914 | P7: =O7/M7 -> -0.036180805 | Q7: =Juni!Q7/31 -> 7863.2581 | R7: =Juni!R7/30 -> 8587.2 | S7: =R7-Q7 -> 723.94194 | T7: =M7-Q7 -> 7369.3811 | U7: =N7-R7 -> 6094.31 | V7: =T7/M7 -> 0.48378886 | W7: =U7/N7 -> 0.41510104
A8: KRIAN | B8: 6499 | C8: 6511 | D8: =Juni!D8/31 -> 22154452 | E8: =Juni!E8/30 -> 23845449 | F8: =E8-D8 -> 1690997 | G8: =F8/D8 -> 0.076327637 | H8: =Juni!H8/31 -> 2708.9677 | I8: =Juni!I8/30 -> 2926.8667 | J8: =Juni!J8/31 -> 3009.6129 | K8: =Juni!K8/30 -> 3212.7333 | L8: =K8/J8 -> 1.0674905 | M8: =Juni!M8/31 -> 5576.9887 | N8: =Juni!N8/30 -> 6144.6883 | O8: =N8-M8 -> 567.69962 | P8: =O8/M8 -> 0.10179322 | Q8: =Juni!Q8/31 -> 3009.6129 | R8: =Juni!R8/30 -> 3212.7333 | S8: =R8-Q8 -> 203.12043 | T8: =M8-Q8 -> 2567.3758 | U8: =N8-R8 -> 2931.955 | V8: =T8/M8 -> 0.46035162 | W8: =U8/N8 -> 0.47715276
A9: TOTAL | B9: =SUM(B2:B8) -> 187292 | C9: =SUM(C2:C8) -> 187700 | D9: =SUM(D2:D8) -> 8.4050409e+08 | E9: =SUM(E2:E8) -> 9.2333347e+08 | H9: =SUM(H2:H8) -> 84621.387 | I9: =SUM(I2:I8) -> 91910.8 | J9: =SUM(J2:J8) -> 101979.65 | K9: =SUM(K2:K8) -> 111464.33 | M9: =SUM(M2:M8)+2472 -> 173614.33 | N9: =SUM(N2:N8)+2427 -> 187163.08 | Q9: =SUM(Q2:Q8)+2129 -> 104108.65 | R9: =SUM(R2:R8)+2486 -> 113950.33 | T9: =SUM(T2:T8)+343 -> 69505.682 | U9: =SUM(U2:U8)+59 -> 73330.744 | V9: =SUM(M9-Q9)/M9 -> 0.40034531 | W9: =SUM(N9-R9)/N9 -> 0.39117087

Sheet Juli
A1: CABANG | B1: JUMLAH PELANGGAN JUNI | C1: JUMLAH PELANGGAN BULAN JULI | D1: PENDAPATAN AIR BULAN JUNI | E1: PENDAPATAN AIR BULAN JULI | F1: SELISIH PENDAPATAN | G1: PRESENTASE PENDAPATAN | H1: KONSUMSI GOL 2 BULAN JUNI | I1: KONSUMSI GOL 2 BULAN JULI | J1: KONSUMSI TOTAL BULAN JUNI | K1: KONSUMSI TOTAL BULAN JULI | L1: PRESENTASE KONSUMSI | M1: AIR DISTRIBUSI BULAN JUNI | N1: AIR DISTRIBUSI BULAN JULI | O1: SELISIH AIR DISTRIBUSI | P1: PRESENTASE SELISIH AIR DISTRIBUSI | Q1: AIR TERJUAL BULAN JUNI | R1: AIR TERJUAL BULAN JULI | S1: SELISIH AIR TERJUAL | T1: TKA BULAN JUNI | U1: TKA BULAN JULI | V1: PRESETASE TKA BULAN JUNI | W1: PRESENTASE TKA BULAN JULI
